Workbook

Sheet 1
A1: บริษัท เอ็นเอ็นวาย แมททีเรียลส์ จำกัด
A2: รายงานการวิ่งรถประจำเดือน | F2: เมษายน | G2: ปี | H2: 2569
A3: เบอร์รถ….1..... | H3: หน้า | I3: 1
A4: ทะเบียนรถ …6001.... | E4: ตั้งแต่วันที่ | F4: 46107 | H4: ถึงวันที่ | I4: 46136
A5: ลำดับ | B5: วันที่ | C5: เลขที่เอกสาร | D5: หน่วยงาน | E5: สินค้า | F5: จำนวนเที่ยว | I5: หมายเหตุ
F6: 8.00-17.00 | G6: หลัง 17.00 | H6: (คิว)
A7: 1 | B7: 46107 | C7: 0071357 | D7: บจก.เอ็นวี | E7: N3200NP00 | F7: 1 | H7: 6
A8: 2 | C8: 0071368 | D8: บจก.เอ็นที | E8: N2400NP00 | F8: 1 | H8: 4
A9: 3 | C9: 0071380 | D9: บริษัท ทีม ยูเนี่ยน | E9: N3201NP01 | F9: 1 | H9: 6
A10: 4 | C10: 0071391 | D10: NTW#2 | E10: N1800NP00 | F10: 1 | H10: 5
A11: 5 | C11: 0071403 | D11: บริษัท ทีม ยูเนี่ยน | E11: N3201NP01 | F11: 1 | H11: 6
A12: 6 | C12: 0071414 | D12: บริษัท ทีม ยูเนี่ยน | E12: N3201NP01 | G12: 1 | H12: 2.5
A13: 7
A14: 8
A15: 9
A16: 10
A17: รวม | F17: =SUM(F7:F16) -> 5 | G17: =SUM(G7:G16) -> 1 | H17: =SUM(H7:H16) -> 29.5
A18: 1 | B18: =B7+1 -> 46108 | C18: 0071416 | D18: บจก.เอ็นวี | E18: N2400NP00 | F18: 1 | H18: 4
A19: 2 | C19: 0071435 | D19: บจก.เซล คอนสตรัคชั่น | E19: N3201NP01 | F19: 1 | H19: 5
A20: 3 | C20: 0071449 | D20: บริษัท ทีม ยูเนี่ยน | E20: N3201NP01 | F20: 1 | H20: 6
A21: 4 | C21: 0071464 | D21: บริษัท ทีม ยูเนี่ยน | E21: N3201NP01 | F21: 1 | H21: 6
A22: 5 | C22: 0071476 | D22: บริษัท ทีม ยูเนี่ยน | E22: N3201NP01 | F22: 1 | H22: 6
A23: 6 | C23: 0071490 | D23: บจก.เซล คอนสตรัคชั่น | E23: N3201NP01 | G23: 1 | H23: 6
A24: 7 | C24: 0071502 | D24: บริษัท ทีม ยูเนี่ยน | E24: N3201NP01 | G24: 1 | H24: 6
A25: 8 | C25: 0071514 | D25: บริษัท ทีม ยูเนี่ยน | E25: N3201NP01 | G25: 1 | H25: 6
A26: 9
A27: 10
A28: รวม | F28: =SUM(F18:F27) -> 5 | G28: =SUM(G18:G27) -> 3 | H28: =SUM(H18:H27) -> 45
A29: 1 | B29: =B18+1 -> 46109 | C29: 0071524 | D29: บจก.ปิยะมณี | E29: N3000NP00 | F29: 1 | H29: 4.5
A30: 2 | C30: 0071536 | D30: บจก.ช.วิรัตน์ | E30: N2400NP00 | F30: 1 | H30: 2
A31: 3 | C31: 0071543 | D31: บจก.ช.วิรัตน์ | E31: N2400NP00 | F31: 1 | H31: 2
A32: 4 | C32: 0071550 | D32: บจก.หลู่ไท่ | E32: N3200NP00 | F32: 1 | H32: 5
A33: 5
A34: 6
A35: 7
A36: 8
A37: 9
A38: 10
A39: รวม | F39: =SUM(F29:F38) -> 4 | G39: =SUM(G29:G38) -> 0 | H39: =SUM(H29:H38) -> 13.5
A40: 1 | B40: =B29+1 -> 46110
...

Sheet 2
A1: บริษัท เอ็นเอ็นวาย แมททีเรียลส์ จำกัด
A2: รายงานการวิ่งรถประจำเดือน | F2: ='1'!$F$2 -> เมษายน | G2: ปี | H2: ='1'!$H$2 -> 2569
A3: เบอร์รถ…2.... | H3: หน้า | I3: 1
A4: ทะเบียนรถ ….6002 .... | E4: ตั้งแต่วันที่ | F4: ='1'!$F$4 -> 46107 | H4: ถึงวันที่ | I4: ='1'!$I$4 -> 46136
A5: ลำดับ | B5: วันที่ | C5: เลขที่เอกสาร | D5: หน่วยงาน | E5: สินค้า | F5: จำนวนเที่ยว | I5: หมายเหตุ
F6: 8.00-17.00 | G6: หลัง 17.00 | H6: (คิว)
A7: 1 | B7: ='1'!B7 -> 46107 | C7: 0071358 | D7: บจก.เอ็นวี | E7: N3200NP00 | F7: 1 | H7: 6
A8: 2 | C8: 0071369 | D8: บจก.เอ็นวี | E8: N3200NP00 | F8: 1 | H8: 6
A9: 3 | C9: 0071396 | D9: บริษัท ทีม ยูเนี่ยน | E9: N3200NP00 | F9: 1 | H9: 2
A10: 4
A11: 5
A12: 6
A13: 7
A14: 8
A15: 9
A16: 10
A17: รวม | F17: =SUM(F7:F16) -> 3 | G17: =SUM(G7:G16) -> 0 | H17: =SUM(H7:H16) -> 14
A18: 1 | B18: =B7+1 -> 46108
A19: 2
A20: 3
A21: 4
A22: 5
A23: 6
A24: 7
A25: 8
A26: 9
A27: 10
A28: รวม | F28: =SUM(F18:F27) -> 0 | G28: =SUM(G18:G27) -> 0 | H28: =SUM(H18:H27) -> 0
A29: 1 | B29: =B18+1 -> 46109 | C29: 0071526 | D29: บจก.หลู่ไท่ | E29: N3200NP00 | F29: 1 | H29: 2.5
A30: 2 | C30: 0071538 | D30: หจก.นัชชา | E30: N2400NP00 | F30: 1 | H30: 1.5
A31: 3 | C31: 0071545 | D31: บจก.ชัชนา | E31: N2400NP00 | F31: 1 | H31: 5
A32: 4
A33: 5
A34: 6
A35: 7
A36: 8
A37: 9
A38: 10
A39: รวม | F39: =SUM(F29:F38) -> 3 | G39: =SUM(G29:G38) -> 0 | H39: =SUM(H29:H38) -> 9
A40: 1 | B40: =B29+1 -> 46110 | C40: 0071555 | D40: บจก.หงส์อัน | E40: N3200NP00 | F40: 1 | H40: 6
...

Sheet 3
A1: บริษัท เอ็นเอ็นวาย แมททีเรียลส์ จำกัด
A2: รายงานการวิ่งรถประจำเดือน | F2: ='1'!$F$2 -> เมษายน | G2: ปี | H2: ='1'!$H$2 -> 2569
A3: เบอร์รถ…3... | H3: หน้า | I3: 1
A4: ทะเบียนรถ …6003 .... | E4: ตั้งแต่วันที่ | F4: ='1'!$F$4 -> 46107 | H4: ถึงวันที่ | I4: ='1'!$I$4 -> 46136
A5: ลำดับ | B5: วันที่ | C5: เลขที่เอกสาร | D5: หน่วยงาน | E5: สินค้า | F5: จำนวนเที่ยว | I5: หมายเหตุ
F6: 8.00-17.00 | G6: หลัง 17.00 | H6: (คิว)
A7: 1 | B7: ='2'!B7 -> 46107 | C7: 0071359 | D7: บจก.เอ็นวี | E7: N3200NP00 | F7: 1 | H7: 6
A8: 2 | C8: 0071370 | D8: บจก.เอ็นวี | E8: N3200NP00 | F8: 1 | H8: 6
A9: 3 | C9: 0071378 | D9: บริษัท ทีม ยูเนี่ยน | E9: N0000NP05 | F9: 1 | H9: 1
A10: 4 | C10: 0071389 | D10: บริษัท ทีม ยูเนี่ยน | E10: N3201NP01 | F10: 1 | H10: 6
A11: 5 | C11: 0071401 | D11: บริษัท ทีม ยูเนี่ยน | E11: N3201NP01 | F11: 1 | H11: 6
A12: 6 | C12: 0071411 | D12: บจก.จิงกง | E12: N1800NP00 | F12: 1 | H12: 6
A13: 7
A14: 8
A15: 9
A16: 10
A17: รวม | F17: =SUM(F7:F16) -> 6 | G17: =SUM(G7:G16) -> 0 | H17: =SUM(H7:H16) -> 31
A18: 1 | B18: =B7+1 -> 46108 | C18: 0071417 | D18: หจก.นัชชา | E18: N2400NP00 | F18: 1 | H18: 5
A19: 2 | C19: 0071428 | D19: ZHC | E19: N3200NP00 | F19: 1 | H19: 4
A20: 3 | C20: 0071442 | D20: บจก.เซล คอนสตรัคชั่น | E20: N3201NP01 | F20: 1 | H20: 5
A21: 4 | C21: 0071462 | D21: บริษัท ทีม ยูเนี่ยน | E21: N3201NP01 | F21: 1 | H21: 6
A22: 5 | C22: 0071475 | D22: บริษัท ทีม ยูเนี่ยน | E22: N3201NP01 | F22: 1 | H22: 6
A23: 6 | C23: 0071489 | D23: บริษัท ทีม ยูเนี่ยน | E23: N3201NP01 | G23: 1 | H23: 6
A24: 7 | C24: 0071501 | D24: บจก.เซล คอนสตรัคชั่น | E24: N3201NP01 | G24: 1 | H24: 6
A25: 8 | C25: 0071515 | D25: บริษัท ทีม ยูเนี่ยน | E25: N3201NP01 | G25: 1 | H25: 2.5
A26: 9
A27: 10
A28: รวม | F28: =SUM(F18:F27) -> 5 | G28: =SUM(G18:G27) -> 3 | H28: =SUM(H18:H27) -> 40.5
A29: 1 | B29: =B18+1 -> 46109 | C29: 0071525 | D29: ZHC | E29: N3200NP00 | F29: 1 | H29: 6
A30: 2 | C30: 0071541 | D30: NTW#2 | E30: N1800NP00 | F30: 1 | H30: 4
A31: 3 | C31: 0071552 | D31: บจก.หลู่ไท่ | E31: N3200NP00 | G31: 1 | H31: 5
A32: 4
A33: 5
A34: 6
A35: 7
A36: 8
A37: 9
A38: 10
A39: รวม | F39: =SUM(F29:F38) -> 2 | G39: =SUM(G29:G38) -> 1 | H39: =SUM(H29:H38) -> 15
A40: 1 | B40: =B29+1 -> 46110 | C40: 0071556 | D40: บริษัท ไทยเซิ่ง | E40: N3200NP00 | F40: 1 | H40: 2
...

Sheet 4
A1: บริษัท เอ็นเอ็นวาย แมททีเรียลส์ จำกัด
A2: รายงานการวิ่งรถประจำเดือน | F2: ='1'!$F$2 -> เมษายน | G2: ปี | H2: ='1'!$H$2 -> 2569
A3: เบอร์รถ…4.... | H3: หน้า | I3: 1
A4: ทะเบียนรถ …6004.... | E4: ตั้งแต่วันที่ | F4: ='1'!$F$4 -> 46107 | H4: ถึงวันที่ | I4: ='1'!$I$4 -> 46136
A5: ลำดับ | B5: วันที่ | C5: เลขที่เอกสาร | D5: หน่วยงาน | E5: สินค้า | F5: จำนวนเที่ยว | I5: หมายเหตุ
F6: 8.00-17.00 | G6: หลัง 17.00 | H6: (คิว)
A7: 1 | B7: ='3'!B7 -> 46107 | C7: 0071360 | D7: บจก.จิงกง | E7: N2800NP00 | F7: 1 | H7: 3
A8: 2 | C8: 0071392 | D8: บริษัท ทีม ยูเนี่ยน | E8: N3201NP01 | F8: 1 | H8: 6
A9: 3 | C9: 0071402 | D9: บริษัท ทีม ยูเนี่ยน | E9: N3201NP01 | F9: 1 | H9: 6
A10: 4 | C10: 0071413 | D10: บริษัท ทีม ยูเนี่ยน | E10: N3201NP01 | F10: 1 | H10: 6
A11: 5
A12: 6
A13: 7
A14: 8
A15: 9
A16: 10
A17: รวม | F17: =SUM(F7:F16) -> 4 | G17: =SUM(G7:G16) -> 0 | H17: =SUM(H7:H16) -> 21
A18: 1 | B18: =B7+1 -> 46108 | C18: 0071418 | D18: หจก.นัชชา | E18: N2400NP00 | F18: 1 | H18: 5
A19: 2 | C19: 0071431 | D19: บจก.เซล คอนสตรัคชั่น | E19: N3201NP01 | F19: 1 | H19: 5
A20: 3 | C20: 0071445 | D20: บจก.เซล คอนสตรัคชั่น | E20: N3201NP01 | F20: 1 | H20: 5
A21: 4 | C21: 0071463 | D21: บจก.เซล คอนสตรัคชั่น | E21: N3201NP01 | F21: 1 | H21: 5
A22: 5 | C22: 0071478 | D22: บริษัท ทีม ยูเนี่ยน | E22: N3201NP01 | F22: 1 | H22: 6
A23: 6 | C23: 0071491 | D23: บริษัท ทีม ยูเนี่ยน | E23: N3201NP01 | G23: 1 | H23: 6
A24: 7 | C24: 0071503 | D24: บจก.เซล คอนสตรัคชั่น | E24: N3201NP01 | G24: 1 | H24: 6
A25: 8
A26: 9
A27: 10
A28: รวม | F28: =SUM(F18:F27) -> 5 | G28: =SUM(G18:G27) -> 2 | H28: =SUM(H18:H27) -> 38
A29: 1 | B29: =B18+1 -> 46109 | C29: 0071516 | D29: NTW#3 | E29: N2800NP00 | F29: 1 | H29: 2.5
A30: 2 | C30: 0071537 | D30: บจก.ชัชนา | E30: N2400NP00 | F30: 1 | H30: 5.5
A31: 3 | C31: 0071548 | D31: ZHC | E31: N3801NP01 | F31: 1 | H31: 3.25
A32: 4
A33: 5
A34: 6
A35: 7
A36: 8
A37: 9
A38: 10
A39: รวม | F39: =SUM(F29:F38) -> 3 | G39: =SUM(G29:G38) -> 0 | H39: =SUM(H29:H38) -> 11.25
A40: 1 | B40: =B29+1 -> 46110 | C40: 0071557 | D40: บจก.หงส์อัน | E40: N3200NP00 | F40: 1 | H40: 6
...

Sheet 5
A1: บริษัท เอ็นเอ็นวาย แมททีเรียลส์ จำกัด
A2: รายงานการวิ่งรถประจำเดือน | F2: ='1'!$F$2 -> เมษายน | G2: ปี | H2: ='1'!$H$2 -> 2569
A3: เบอร์รถ….5...... | H3: หน้า | I3: 1
A4: ทะเบียนรถ ….6005..... | E4: ตั้งแต่วันที่ | F4: ='1'!$F$4 -> 46107 | H4: ถึงวันที่ | I4: ='1'!$I$4 -> 46136
A5: ลำดับ | B5: วันที่ | C5: เลขที่เอกสาร | D5: หน่วยงาน | E5: สินค้า | F5: จำนวนเที่ยว | I5: หมายเหตุ
F6: 8.00-17.00 | G6: หลัง 17.00 | H6: (คิว)
A7: 1 | B7: ='4'!B7 -> 46107 | C7: 0071361 | D7: บจก.เอ็นวี | E7: N3200NP00 | F7: 1 | H7: 6
A8: 2 | C8: 0071371 | D8: กวิน อ้นขวัญเมือง | E8: N2400NP00 | F8: 1 | H8: 3
A9: 3 | C9: 0071383 | D9: บริษัท ทีม ยูเนี่ยน | E9: N3201NP01 | F9: 1 | H9: 6
A10: 4 | C10: 0071394 | D10: บริษัท ทีม ยูเนี่ยน | E10: N3201NP01 | F10: 1 | H10: 6
A11: 5 | C11: 0071405 | D11: บริษัท ทีม ยูเนี่ยน | E11: N3201NP01 | F11: 1 | H11: 6
A12: 6
A13: 7
A14: 8
A15: 9
A16: 10
A17: รวม | F17: =SUM(F7:F16) -> 5 | G17: =SUM(G7:G16) -> 0 | H17: =SUM(H7:H16) -> 27
A18: 1 | B18: =B7+1 -> 46108 | C18: 0071419 | D18: หจก.นัชชา | E18: N2400NP00 | F18: 1 | H18: 5
A19: 2 | C19: 0071432 | D19: บจก.เซล คอนสตรัคชั่น | E19: N3201NP01 | F19: 1 | H19: 5
A20: 3 | C20: 0071446 | D20: บริษัท ทีม ยูเนี่ยน | E20: N3201NP01 | F20: 1 | H20: 6
A21: 4 | C21: 0071457 | D21: บริษัท ทีม ยูเนี่ยน | E21: N3201NP01 | F21: 1 | H21: 6
A22: 5 | C22: 0071471 | D22: บริษัท ทีม ยูเนี่ยน | E22: N3201NP01 | F22: 1 | H22: 6
A23: 6 | C23: 0071484 | D23: บจก.เซล คอนสตรัคชั่น | E23: N3201NP01 | F23: 1 | H23: 6
A24: 7 | C24: 0071513 | D24: บริษัท ทีม ยูเนี่ยน | E24: N3201NP01 | G24: 1 | H24: 6
A25: 8
A26: 9
A27: 10
A28: รวม | F28: =SUM(F18:F27) -> 6 | G28: =SUM(G18:G27) -> 1 | H28: =SUM(H18:H27) -> 40
A29: 1 | B29: =B18+1 -> 46109 | C29: 0071517 | D29: หจก.นัชชา | E29: N2400NP00 | F29: 1 | H29: 5
A30: 2 | C30: 0071529 | D30: หจก.นัชชา | E30: N2400NP00 | F30: 1 | H30: 5
A31: 3 | C31: 0071544 | D31: NTW#2 | E31: N1800NP00 | F31: 1 | H31: 4
A32: 4
A33: 5
A34: 6
A35: 7
A36: 8
A37: 9
A38: 10
A39: รวม | F39: =SUM(F29:F38) -> 3 | G39: =SUM(G29:G38) -> 0 | H39: =SUM(H29:H38) -> 14
A40: 1 | B40: =B29+1 -> 46110 | C40: 0071558 | D40: บจก.หงส์อัน | E40: N3200NP00 | F40: 1 | H40: 6
...

Sheet 6
A1: บริษัท เอ็นเอ็นวาย แมททีเรียลส์ จำกัด
A2: รายงานการวิ่งรถประจำเดือน | F2: ='1'!$F$2 -> เมษายน | G2: ปี | H2: ='1'!$H$2 -> 2569
A3: เบอร์รถ…6.... | H3: หน้า | I3: 1
A4: ทะเบียนรถ …6006.... | E4: ตั้งแต่วันที่ | F4: ='1'!$F$4 -> 46107 | H4: ถึงวันที่ | I4: ='1'!$I$4 -> 46136
A5: ลำดับ | B5: วันที่ | C5: เลขที่เอกสาร | D5: หน่วยงาน | E5: สินค้า | F5: จำนวนเที่ยว | I5: หมายเหตุ
F6: 8.00-17.00 | G6: หลัง 17.00 | H6: (คิว)
A7: 1 | B7: ='5'!B7 -> 46107
A8: 2
A9: 3
A10: 4
A11: 5
A12: 6
A13: 7
A14: 8
A15: 9
A16: 10
A17: รวม | F17: =SUM(F7:F16) -> 0 | G17: =SUM(G7:G16) -> 0 | H17: =SUM(H7:H16) -> 0
A18: 1 | B18: =B7+1 -> 46108 | C18: 0071420 | D18: บริษัท โหลงไท่ | E18: N0000NP05 | F18: 1 | H18: 5
A19: 2 | C19: 0071436 | D19: บจก.เซล คอนสตรัคชั่น | E19: N3201NP01 | F19: 1 | H19: 5
A20: 3 | C20: 0071450 | D20: บจก.ชัชนา | E20: N2400NP00 | F20: 1 | H20: 5.5
A21: 4 | C21: 0071467 | D21: บริษัท ทีม ยูเนี่ยน | E21: N3201NP01 | F21: 1 | H21: 6
A22: 5 | C22: 0071479 | D22: บริษัท ทีม ยูเนี่ยน | E22: N3201NP01 | F22: 1 | H22: 6
A23: 6 | C23: 0071494 | D23: บจก.เซล คอนสตรัคชั่น | E23: N3201NP01 | G23: 1 | H23: 6
A24: 7 | C24: 0071507 | D24: บริษัท ทีม ยูเนี่ยน | E24: N3201NP01 | G24: 1 | H24: 6
A25: 8
A26: 9
A27: 10
A28: รวม | F28: =SUM(F18:F27) -> 5 | G28: =SUM(G18:G27) -> 2 | H28: =SUM(H18:H27) -> 39.5
A29: 1 | B29: =B18+1 -> 46109 | C29: 0071518 | D29: หจก.นัชชา | E29: N2400NP00 | F29: 1 | H29: 5
A30: 2 | C30: 0071530 | D30: บจก.ปิยะมณี | E30: N3000NP00 | F30: 1 | H30: 4
A31: 3 | C31: 0071549 | D31: บจก.หลู่ไท่ | E31: N3200NP00 | F31: 1 | H31: 5
A32: 4
A33: 5
A34: 6
A35: 7
A36: 8
A37: 9
A38: 10
A39: รวม | F39: =SUM(F29:F38) -> 3 | G39: =SUM(G29:G38) -> 0 | H39: =SUM(H29:H38) -> 14
A40: 1 | B40: =B29+1 -> 46110 | C40: 0071559 | D40: บจก.หงส์อัน | E40: N3200NP00 | F40: 1 | H40: 6
...

Sheet 7
A1: บริษัท เอ็นเอ็นวาย แมททีเรียลส์ จำกัด
A2: รายงานการวิ่งรถประจำเดือน | F2: ='1'!$F$2 -> เมษายน | G2: ปี | H2: ='1'!$H$2 -> 2569
A3: เบอร์รถ…6007.... | H3: หน้า | I3: 1
A4: ทะเบียนรถ …6007 ... | E4: ตั้งแต่วันที่ | F4: ='1'!$F$4 -> 46107 | H4: ถึงวันที่ | I4: ='1'!$I$4 -> 46136
A5: ลำดับ | B5: วันที่ | C5: เลขที่เอกสาร | D5: หน่วยงาน | E5: สินค้า | F5: จำนวนเที่ยว | I5: หมายเหตุ
F6: 8.00-17.00 | G6: หลัง 17.00 | H6: (คิว)
A7: 1 | B7: ='6'!B7 -> 46107 | C7: 0071362 | D7: บจก.เอ็นวี | E7: N3200NP00 | F7: 1 | H7: 6
A8: 2 | C8: 0071373 | D8: บจก.หู่เฟิง | E8: N3200NP00 | F8: 1 | H8: 5
A9: 3 | C9: 0071386 | D9: NTW#2 | E9: N1800NP00 | F9: 1 | H9: 5
A10: 4 | C10: 0071399 | D10: บริษัท ทีม ยูเนี่ยน | E10: N3201NP01 | F10: 1 | H10: 6
A11: 5 | C11: 0071409 | D11: บจก.หอพักสาย19 | E11: N3201NP01 | F11: 1 | H11: 5
A12: 6
A13: 7
A14: 8
A15: 9
A16: 10
A17: รวม | F17: =SUM(F7:F16) -> 5 | G17: =SUM(G7:G16) -> 0 | H17: =SUM(H7:H16) -> 27
A18: 1 | B18: =B7+1 -> 46108 | C18: 0071421 | D18: บจก.สุขนภา | E18: N2400NP00 | F18: 1 | H18: 5
A19: 2 | C19: 0071430 | D19: บจก.เซล คอนสตรัคชั่น | E19: N0000NP05 | F19: 1 | H19: 1
A20: 3 | C20: 0071444 | D20: บริษัท ทีม ยูเนี่ยน | E20: N3201NP01 | F20: 1 | H20: 6
A21: 4 | C21: 0071454 | D21: บจก.เซล คอนสตรัคชั่น | E21: N3201NP01 | F21: 1 | H21: 5
A22: 5 | C22: 0071474 | D22: บริษัท ทีม ยูเนี่ยน | E22: N3201NP01 | F22: 1 | H22: 6
A23: 6 | C23: 0071487 | D23: บจก.เซล คอนสตรัคชั่น | E23: N3201NP01 | G23: 1 | H23: 6
A24: 7 | C24: 0071497 | D24: บริษัท ทีม ยูเนี่ยน | E24: N3201NP01 | G24: 1 | H24: 6
A25: 8 | C25: 0071509 | D25: บริษัท ทีม ยูเนี่ยน | E25: N3201NP01 | G25: 1 | H25: 6
A26: 9
A27: 10
A28: รวม | F28: =SUM(F18:F27) -> 5 | G28: =SUM(G18:G27) -> 3 | H28: =SUM(H18:H27) -> 41
A29: 1 | B29: =B18+1 -> 46109
A30: 2
A31: 3
A32: 4
A33: 5
A34: 6
A35: 7
A36: 8
A37: 9
A38: 10
A39: รวม | F39: =SUM(F29:F38) -> 0 | G39: =SUM(G29:G38) -> 0 | H39: =SUM(H29:H38) -> 0
A40: 1 | B40: =B29+1 -> 46110
...

Sheet 8
A1: บริษัท เอ็นเอ็นวาย แมททีเรียลส์ จำกัด
A2: รายงานการวิ่งรถประจำเดือน | F2: ='1'!$F$2 -> เมษายน | G2: ปี | H2: ='1'!$H$2 -> 2569
A3: เบอร์รถ…8... | H3: หน้า | I3: 1
A4: ทะเบียนรถ …6008 .... | E4: ตั้งแต่วันที่ | F4: ='1'!$F$4 -> 46107 | H4: ถึงวันที่ | I4: ='1'!$I$4 -> 46136
A5: ลำดับ | B5: วันที่ | C5: เลขที่เอกสาร | D5: หน่วยงาน | E5: สินค้า | F5: จำนวนเที่ยว | I5: หมายเหตุ
F6: 8.00-17.00 | G6: หลัง 17.00 | H6: (คิว)
A7: 1 | B7: ='7'!B7 -> 46107 | C7: 0071363 | D7: บจก.เอ็นวี | E7: N3200NP00 | F7: 1 | H7: 6
A8: 2 | C8: 0071372 | D8: บริษัท โหลงไท่ | E8: N3200NP00 | F8: 1 | H8: 2.5
A9: 3 | C9: 0071379 | D9: บริษัท ทีม ยูเนี่ยน | E9: N3201NP01 | F9: 1 | H9: 6
A10: 4 | C10: 0071390 | D10: บจก.จิงกง | E10: N1800NP00 | F10: 1 | H10: 5
A11: 5 | C11: 0071412 | D11: บริษัท ทีม ยูเนี่ยน | E11: N3201NP01 | F11: 1 | H11: 6
A12: 6
A13: 7
A14: 8
A15: 9
A16: 10
A17: รวม | F17: =SUM(F7:F16) -> 5 | G17: =SUM(G7:G16) -> 0 | H17: =SUM(H7:H16) -> 25.5
A18: 1 | B18: =B7+1 -> 46108 | C18: 0071422 | D18: บจก.สุขนภา | E18: N2400NP00 | F18: 1 | H18: 5
A19: 2 | C19: 0071433 | D19: บจก.เซล คอนสตรัคชั่น | E19: N3201NP01 | F19: 1 | H19: 5
A20: 3 | C20: 0071447 | D20: บริษัท ทีม ยูเนี่ยน | E20: N3201NP01 | F20: 1 | H20: 6
A21: 4 | C21: 0071460 | D21: บริษัท ทีม ยูเนี่ยน | E21: N3201NP01 | F21: 1 | H21: 6
A22: 5 | C22: 0071472 | D22: บจก.เซล คอนสตรัคชั่น | E22: N3201NP01 | F22: 1 | H22: 5
A23: 6 | C23: 0071485 | D23: บริษัท ทีม ยูเนี่ยน | E23: N3201NP01 | F23: 1 | H23: 6
A24: 7 | C24: 0071499 | D24: บจก.เซล คอนสตรัคชั่น | E24: N3201NP01 | G24: 1 | H24: 6
A25: 8 | C25: 0071511 | D25: บจก.เซล คอนสตรัคชั่น | E25: N3201NP01 | G25: 1 | H25: 6
A26: 9
A27: 10
A28: รวม | F28: =SUM(F18:F27) -> 6 | G28: =SUM(G18:G27) -> 2 | H28: =SUM(H18:H27) -> 45
A29: 1 | B29: =B18+1 -> 46109 | C29: 0071519 | D29: บจก.ช.วิรัตน์ | E29: N2400NP00 | F29: 1 | H29: 3
A30: 2 | C30: 0071534 | D30: บจก.ชัชนา | E30: N2400NP00 | F30: 1 | H30: 5.5
A31: 3 | C31: 0071553 | D31: บจก.หลู่ไท่ | E31: N3200NP00 | G31: 1 | H31: 5.5
A32: 4
A33: 5
A34: 6
A35: 7
A36: 8
A37: 9
A38: 10
A39: รวม | F39: =SUM(F29:F38) -> 2 | G39: =SUM(G29:G38) -> 1 | H39: =SUM(H29:H38) -> 14
A40: 1 | B40: =B29+1 -> 46110 | C40: 0071560 | D40: บจก.หงส์อัน | E40: N3200NP00 | F40: 1 | H40: 6
...

Sheet 9
A1: บริษัท เอ็นเอ็นวาย แมททีเรียลส์ จำกัด
A2: รายงานการวิ่งรถประจำเดือน | F2: ='1'!$F$2 -> เมษายน | G2: ปี | H2: ='1'!$H$2 -> 2569
A3: เบอร์รถ…9.... | H3: หน้า | I3: 1
A4: ทะเบียนรถ …6009 .... | E4: ตั้งแต่วันที่ | F4: ='1'!$F$4 -> 46107 | H4: ถึงวันที่ | I4: ='1'!$I$4 -> 46136
A5: ลำดับ | B5: วันที่ | C5: เลขที่เอกสาร | D5: หน่วยงาน | E5: สินค้า | F5: จำนวนเที่ยว | I5: หมายเหตุ
F6: 8.00-17.00 | G6: หลัง 17.00 | H6: (คิว)
A7: 1 | B7: ='8'!B7 -> 46107 | C7: 0071364 | D7: บจก.เอ็นวี | E7: N3200NP00 | F7: 1 | H7: 6
A8: 2 | C8: 0071375 | D8: ธนกร ศรีพุทธา | E8: N3000NP00 | F8: 1 | H8: 5.5
A9: 3 | C9: 0071385 | D9: บริษัท ทีม ยูเนี่ยน | E9: N3201NP01 | F9: 1 | H9: 6
A10: 4 | C10: 0071397 | D10: บริษัท ทีม ยูเนี่ยน | E10: N3201NP01 | F10: 1 | H10: 6
A11: 5 | C11: 0071407 | D11: บริษัท ทีม ยูเนี่ยน | E11: N3201NP01 | F11: 1 | H11: 6
A12: 6
A13: 7
A14: 8
A15: 9
A16: 10
A17: รวม | F17: =SUM(F7:F16) -> 5 | G17: =SUM(G7:G16) -> 0 | H17: =SUM(H7:H16) -> 29.5
A18: 1 | B18: =B7+1 -> 46108 | C18: 0071424 | D18: บจก.สุขนภา | E18: N2400NP00 | F18: 1 | H18: 5
A19: 2 | C19: 0071437 | D19: บจก.เซล คอนสตรัคชั่น | E19: N3201NP01 | F19: 1 | H19: 5
A20: 3 | C20: 0071451 | D20: บริษัท ทีม ยูเนี่ยน | E20: N3201NP01 | F20: 1 | H20: 6
A21: 4 | C21: 0071468 | D21: บจก.เซล คอนสตรัคชั่น | E21: N3201NP01 | F21: 1 | H21: 5
A22: 5 | C22: 0071480 | D22: บจก.เซล คอนสตรัคชั่น | E22: N3201NP01 | F22: 1 | H22: 6
A23: 6 | C23: 0071492 | D23: บจก.เซล คอนสตรัคชั่น | E23: N3201NP01 | G23: 1 | H23: 6
A24: 7 | C24: 0071506 | D24: บริษัท ทีม ยูเนี่ยน | E24: N3201NP01 | G24: 1 | H24: 6
A25: 8
A26: 9
A27: 10
A28: รวม | F28: =SUM(F18:F27) -> 5 | G28: =SUM(G18:G27) -> 2 | H28: =SUM(H18:H27) -> 39
A29: 1 | B29: =B18+1 -> 46109 | C29: 0071520 | D29: บจก.ปิยะมณี | E29: N3000NP00 | F29: 1 | H29: 4.5
A30: 2 | C30: 0071533 | D30: บจก.วิธา | E30: N2400NP00 | F30: 1 | H30: 4.75
A31: 3
A32: 4
A33: 5
A34: 6
A35: 7
A36: 8
A37: 9
A38: 10
A39: รวม | F39: =SUM(F29:F38) -> 2 | G39: =SUM(G29:G38) -> 0 | H39: =SUM(H29:H38) -> 9.25
A40: 1 | B40: =B29+1 -> 46110 | C40: 0071564 | D40: บจก.เซล คอนสตรัคชั่น | E40: N3201NP01 | F40: 1 | H40: 5.5
...

Sheet 10
A1: บริษัท เอ็นเอ็นวาย แมททีเรียลส์ จำกัด
A2: รายงานการวิ่งรถประจำเดือน | F2: ='1'!$F$2 -> เมษายน | G2: ปี | H2: ='1'!$H$2 -> 2569
A3: เบอร์รถ…10.... | H3: หน้า | I3: 1
A4: ทะเบียนรถ …6010.... | E4: ตั้งแต่วันที่ | F4: ='1'!$F$4 -> 46107 | H4: ถึงวันที่ | I4: ='1'!$I$4 -> 46136
A5: ลำดับ | B5: วันที่ | C5: เลขที่เอกสาร | D5: หน่วยงาน | E5: สินค้า | F5: จำนวนเที่ยว | I5: หมายเหตุ
F6: 8.00-17.00 | G6: หลัง 17.00 | H6: (คิว)
A7: 1 | B7: ='9'!B7 -> 46107 | C7: 0071365 | D7: บริษัท โหลงไท่ | E7: N3200NP00 | F7: 1 | H7: 5
A8: 2 | C8: 0071374 | D8: บจก.หู่เฟิง | E8: N0000NP00 | F8: 1 | H8: 2
A9: 3 | C9: 0071384 | D9: บริษัท ทีม ยูเนี่ยน | E9: N3201NP01 | F9: 1 | H9: 6
A10: 4 | C10: 0071395 | D10: บริษัท ทีม ยูเนี่ยน | E10: N3201NP01 | F10: 1 | H10: 6
A11: 5 | C11: 0071406 | D11: บริษัท ทีม ยูเนี่ยน | E11: N3200NP00 | F11: 1 | H11: 6
A12: 6
A13: 7
A14: 8
A15: 9
A16: 10
A17: รวม | F17: =SUM(F7:F16) -> 5 | G17: =SUM(G7:G16) -> 0 | H17: =SUM(H7:H16) -> 25
A18: 1 | B18: =B7+1 -> 46108 | C18: 0071425 | D18: บริษัท โหลงไท่ | E18: N0000NP05 | F18: 1 | H18: 5
A19: 2 | C19: 0071443 | D19: บริษัท ทีม ยูเนี่ยน | E19: N0000NP05 | F19: 1 | H19: 1
A20: 3 | C20: 0071452 | D20: บจก.เซล คอนสตรัคชั่น | E20: N3201NP01 | F20: 1 | H20: 5
A21: 4 | C21: 0071466 | D21: บจก.ชัชนา | E21: N2400NP00 | F21: 1 | H21: 5.5
A22: 5 | C22: 0071483 | D22: บริษัท ทีม ยูเนี่ยน | E22: N3201NP01 | F22: 1 | H22: 6
A23: 6 | C23: 0071495 | D23: บริษัท ทีม ยูเนี่ยน | E23: N3201NP01 | G23: 1 | H23: 6
A24: 7 | C24: 0071505 | D24: บจก.เซล คอนสตรัคชั่น | E24: N3201NP01 | G24: 1 | H24: 6
A25: 8
A26: 9
A27: 10
A28: รวม | F28: =SUM(F18:F27) -> 5 | G28: =SUM(G18:G27) -> 2 | H28: =SUM(H18:H27) -> 34.5
A29: 1 | B29: =B18+1 -> 46109 | C29: 0071521 | D29: หจก.นัชชา | E29: N2400NP00 | F29: 1 | H29: 5
A30: 2 | C30: 0071531 | D30: บจก.ไทย สตีล | E30: N1800NP00 | F30: 1 | H30: 6
A31: 3 | C31: 0071546 | D31: บจก.หลู่ไท่ | E31: N3200NP00 | F31: 1 | H31: 5
A32: 4
A33: 5
A34: 6
A35: 7
A36: 8
A37: 9
A38: 10
A39: รวม | F39: =SUM(F29:F38) -> 3 | G39: =SUM(G29:G38) -> 0 | H39: =SUM(H29:H38) -> 16
A40: 1 | B40: =B29+1 -> 46110 | C40: 0071561 | D40: บจก.หงส์อัน | E40: N3200NP00 | F40: 1 | H40: 6
...

Sheet 11
A1: บริษัท เอ็นเอ็นวาย แมททีเรียลส์ จำกัด
A2: รายงานการวิ่งรถประจำเดือน | F2: ='1'!$F$2 -> เมษายน | G2: ปี | H2: ='1'!$H$2 -> 2569
A3: เบอร์รถ…10.... | H3: หน้า | I3: 1
A4: ทะเบียนรถ …6010.... | E4: ตั้งแต่วันที่ | F4: ='1'!$F$4 -> 46107 | H4: ถึงวันที่ | I4: ='1'!$I$4 -> 46136
A5: ลำดับ | B5: วันที่ | C5: เลขที่เอกสาร | D5: หน่วยงาน | E5: สินค้า | F5: จำนวนเที่ยว | I5: หมายเหตุ
F6: 8.00-17.00 | G6: หลัง 17.00 | H6: (คิว)
A7: 1 | B7: ='9'!B7 -> 46107 | C7: 0071366 | D7: บจก.เอ็นวี | E7: N3200NP00 | F7: 1 | H7: 6
A8: 2 | C8: 0071377 | D8: NTW#2 | E8: N1800NP00 | F8: 1 | H8: 5
A9: 3 | C9: 0071388 | D9: บริษัท ทีม ยูเนี่ยน | E9: N3201NP01 | F9: 1 | H9: 6
A10: 4 | C10: 0071398 | D10: บริษัท ทีม ยูเนี่ยน | E10: N3201NP01 | F10: 1 | H10: 6
A11: 5 | C11: 0071408 | D11: บริษัท ทีม ยูเนี่ยน | E11: N3201NP01 | F11: 1 | H11: 6
A12: 6
A13: 7
A14: 8
A15: 9
A16: 10
A17: รวม | F17: =SUM(F7:F16) -> 5 | G17: =SUM(G7:G16) -> 0 | H17: =SUM(H7:H16) -> 29
A18: 1 | B18: =B7+1 -> 46108 | C18: 0071426 | D18: บจก.จิงกง | E18: N3200NP00 | F18: 1 | H18: 5
A19: 2 | C19: 0071439 | D19: บจก.เซล คอนสตรัคชั่น | E19: N3201NP01 | F19: 1 | H19: 5
A20: 3 | C20: 0071456 | D20: บริษัท ทีม ยูเนี่ยน | E20: N3201NP01 | F20: 1 | H20: 6
A21: 4 | C21: 0071469 | D21: บริษัท ทีม ยูเนี่ยน | E21: N3201NP01 | F21: 1 | H21: 6
A22: 5 | C22: 0071481 | D22: บจก.ชัชนา | E22: N2400NP00 | F22: 1 | H22: 5
A23: 6 | C23: 0071493 | D23: บริษัท ทีม ยูเนี่ยน | E23: N3201NP01 | G23: 1 | H23: 6
A24: 7 | C24: 0071504 | D24: บริษัท ทีม ยูเนี่ยน | E24: N3201NP01 | G24: 1 | H24: 6
A25: 8
A26: 9
A27: 10
A28: รวม | F28: =SUM(F18:F27) -> 5 | G28: =SUM(G18:G27) -> 2 | H28: =SUM(H18:H27) -> 39
A29: 1 | B29: =B18+1 -> 46109 | C29: 0071522 | D29: บจก.ไทย สตีล | E29: N3200NP00 | F29: 1 | H29: 6
A30: 2 | C30: 0071532 | D30: บจก.ไทย สตีล | E30: N3200NP00 | F30: 1 | H30: 6
A31: 3 | C31: 0071547 | D31: บริษัท ทีม ยูเนี่ยน | E31: N1800NP00 | F31: 1 | H31: 6
A32: 4
A33: 5
A34: 6
A35: 7
A36: 8
A37: 9
A38: 10
A39: รวม | F39: =SUM(F29:F38) -> 3 | G39: =SUM(G29:G38) -> 0 | H39: =SUM(H29:H38) -> 18
A40: 1 | B40: =B29+1 -> 46110 | C40: 0071563 | D40: บจก.เซล คอนสตรัคชั่น | E40: N0000NP05 | F40: 1 | H40: 1
...

Sheet 12
A1: บริษัท เอ็นเอ็นวาย แมททีเรียลส์ จำกัด
A2: รายงานการวิ่งรถประจำเดือน | F2: ='1'!$F$2 -> เมษายน | G2: ปี | H2: ='1'!$H$2 -> 2569
A3: เบอร์รถ…10.... | H3: หน้า | I3: 1
A4: ทะเบียนรถ …6010.... | E4: ตั้งแต่วันที่ | F4: ='1'!$F$4 -> 46107 | H4: ถึงวันที่ | I4: ='1'!$I$4 -> 46136
A5: ลำดับ | B5: วันที่ | C5: เลขที่เอกสาร | D5: หน่วยงาน | E5: สินค้า | F5: จำนวนเที่ยว | I5: หมายเหตุ
F6: 8.00-17.00 | G6: หลัง 17.00 | H6: (คิว)
A7: 1 | B7: ='9'!B7 -> 46107 | C7: 0071356 | D7: บจก.เอ็นวี | E7: N3200NP00 | F7: 1 | H7: 6
A8: 2 | C8: 0071367 | D8: บริษัท โหลงไท่ | E8: N3200NP00 | F8: 1 | H8: 5
A9: 3 | C9: 0071376 | D9: บจก.เอ็นวี | E9: N3200NP00 | F9: 1 | H9: 6
A10: 4 | C10: 0071381 | D10: บริษัท ทีม ยูเนี่ยน | E10: N3201NP01 | F10: 1 | H10: 6
A11: 5 | C11: 0071393 | D11: บริษัท ทีม ยูเนี่ยน | E11: N3201NP01 | F11: 1 | H11: 6
A12: 6 | C12: 0071404 | D12: บริษัท ทีม ยูเนี่ยน | E12: N3201NP01 | F12: 1 | H12: 6
A13: 7
A14: 8
A15: 9
A16: 10
A17: รวม | F17: =SUM(F7:F16) -> 6 | G17: =SUM(G7:G16) -> 0 | H17: =SUM(H7:H16) -> 35
A18: 1 | B18: =B7+1 -> 46108 | C18: 0071415 | D18: บจก.จิงกง | E18: N3200NP00 | F18: 1 | H18: 5
A19: 2 | C19: 0071434 | D19: บจก.เซล คอนสตรัคชั่น | E19: N3201NP01 | F19: 1 | H19: 5
A20: 3 | C20: 0071448 | D20: บริษัท ทีม ยูเนี่ยน | E20: N3201NP01 | F20: 1 | H20: 6
A21: 4 | C21: 0071461 | D21: บริษัท ทีม ยูเนี่ยน | E21: N3201NP01 | F21: 1 | H21: 6
A22: 5 | C22: 0071473 | D22: บจก.เซล คอนสตรัคชั่น | E22: N3201NP01 | F22: 1 | H22: 5
A23: 6 | C23: 0071486 | D23: บริษัท ทีม ยูเนี่ยน | E23: N3201NP01 | F23: 1 | H23: 6
A24: 7 | C24: 0071500 | D24: บริษัท ทีม ยูเนี่ยน | E24: N3201NP01 | G24: 1 | H24: 6
A25: 8 | C25: 0071512 | D25: บจก.เซล คอนสตรัคชั่น | E25: N3201NP01 | G25: 1 | H25: 6
A26: 9
A27: 10
A28: รวม | F28: =SUM(F18:F27) -> 6 | G28: =SUM(G18:G27) -> 2 | H28: =SUM(H18:H27) -> 45
A29: 1 | B29: =B18+1 -> 46109 | C29: 0071523 | D29: บจก.วิธา | E29: N2400NP00 | F29: 1 | H29: 4.75
A30: 2 | C30: 0071535 | D30: ZHC | E30: N3801NP01 | F30: 1 | H30: 5
A31: 3
A32: 4
A33: 5
A34: 6
A35: 7
A36: 8
A37: 9
A38: 10
A39: รวม | F39: =SUM(F29:F38) -> 2 | G39: =SUM(G29:G38) -> 0 | H39: =SUM(H29:H38) -> 9.75
A40: 1 | B40: =B29+1 -> 46110 | C40: 0071554 | D40: บจก.หงส์อัน | E40: N3200NP00 | F40: 1 | H40: 6
...

Sheet 13
A1: บริษัท เอ็นเอ็นวาย แมททีเรียลส์ จำกัด
A2: รายงานการวิ่งรถประจำเดือน | F2: ='1'!$F$2 -> เมษายน | G2: ปี | H2: ='1'!$H$2 -> 2569
A3: เบอร์รถ…10.... | H3: หน้า | I3: 1
A4: ทะเบียนรถ …6010.... | E4: ตั้งแต่วันที่ | F4: ='1'!$F$4 -> 46107 | H4: ถึงวันที่ | I4: ='1'!$I$4 -> 46136
A5: ลำดับ | B5: วันที่ | C5: เลขที่เอกสาร | D5: หน่วยงาน | E5: สินค้า | F5: จำนวนเที่ยว | I5: หมายเหตุ
F6: 8.00-17.00 | G6: หลัง 17.00 | H6: (คิว)
A7: 1 | B7: ='9'!B7 -> 46107 | C7: 0071387 | D7: บริษัท ทีม ยูเนี่ยน | E7: N3201NP01 | F7: 1 | H7: 6
A8: 2 | C8: 0071400 | D8: บริษัท ทีม ยูเนี่ยน | E8: N3201NP01 | F8: 1 | H8: 6
A9: 3 | C9: 0071410 | D9: บริษัท ทีม ยูเนี่ยน | E9: N3201NP01 | F9: 1 | H9: 6
A10: 4
A11: 5
A12: 6
A13: 7
A14: 8
A15: 9
A16: 10
A17: รวม | F17: =SUM(F7:F16) -> 3 | G17: =SUM(G7:G16) -> 0 | H17: =SUM(H7:H16) -> 18
A18: 1 | B18: =B7+1 -> 46108 | C18: 0071423 | D18: บริษัท โหลงไท่ | E18: N3201NP01 | F18: 1 | H18: 1.5
A19: 2 | C19: 0071440 | D19: บจก.หู่เฟิง | E19: N0000NP00 | F19: 1 | H19: 2
A20: 3 | C20: 0071465 | D20: บริษัท ทีม ยูเนี่ยน | E20: N3200NP00 | F20: 1 | H20: 2
A21: 4 | C21: 0071488 | D21: บริษัท ทีม ยูเนี่ยน | E21: N3200NP00 | G21: 1 | H21: 2
A22: 5
A23: 6
A24: 7
A25: 8
A26: 9
A27: 10
A28: รวม | F28: =SUM(F18:F27) -> 3 | G28: =SUM(G18:G27) -> 1 | H28: =SUM(H18:H27) -> 7.5
A29: 1 | B29: =B18+1 -> 46109
A30: 2
A31: 3
A32: 4
A33: 5
A34: 6
A35: 7
A36: 8
A37: 9
A38: 10
A39: รวม | F39: =SUM(F29:F38) -> 0 | G39: =SUM(G29:G38) -> 0 | H39: =SUM(H29:H38) -> 0
A40: 1 | B40: =B29+1 -> 46110 | C40: 0071568 | D40: บจก.เซล คอนสตรัคชั่น | E40: N3201NP01 | F40: 1 | H40: 5.5
...

Sheet 14
A1: บริษัท เอ็นเอ็นวาย แมททีเรียลส์ จำกัด
A2: รายงานการวิ่งรถประจำเดือน | F2: ='1'!$F$2 -> เมษายน | G2: ปี | H2: ='1'!$H$2 -> 2569
A3: เบอร์รถ…10.... | H3: หน้า | I3: 1
A4: ทะเบียนรถ …6010.... | E4: ตั้งแต่วันที่ | F4: ='1'!$F$4 -> 46107 | H4: ถึงวันที่ | I4: ='1'!$I$4 -> 46136
A5: ลำดับ | B5: วันที่ | C5: เลขที่เอกสาร | D5: หน่วยงาน | E5: สินค้า | F5: จำนวนเที่ยว | I5: หมายเหตุ
F6: 8.00-17.00 | G6: หลัง 17.00 | H6: (คิว)
A7: 1 | B7: ='9'!B7 -> 46107
A8: 2
A9: 3
A10: 4
A11: 5
A12: 6
A13: 7
A14: 8
A15: 9
A16: 10
A17: รวม | F17: =SUM(F7:F16) -> 0 | G17: =SUM(G7:G16) -> 0 | H17: =SUM(H7:H16) -> 0
A18: 1 | B18: =B7+1 -> 46108
A19: 2
A20: 3
A21: 4
A22: 5
A23: 6
A24: 7
A25: 8
A26: 9
A27: 10
A28: รวม | F28: =SUM(F18:F27) -> 0 | G28: =SUM(G18:G27) -> 0 | H28: =SUM(H18:H27) -> 0
A29: 1 | B29: =B18+1 -> 46109
A30: 2
A31: 3
A32: 4
A33: 5
A34: 6
A35: 7
A36: 8
A37: 9
A38: 10
A39: รวม | F39: =SUM(F29:F38) -> 0 | G39: =SUM(G29:G38) -> 0 | H39: =SUM(H29:H38) -> 0
A40: 1 | B40: =B29+1 -> 46110
...

Sheet 15
A1: บริษัท เอ็นเอ็นวาย แมททีเรียลส์ จำกัด
A2: รายงานการวิ่งรถประจำเดือน | F2: ='1'!$F$2 -> เมษายน | G2: ปี | H2: ='1'!$H$2 -> 2569
A3: เบอร์รถ…10.... | H3: หน้า | I3: 1
A4: ทะเบียนรถ …6010.... | E4: ตั้งแต่วันที่ | F4: ='1'!$F$4 -> 46107 | H4: ถึงวันที่ | I4: ='1'!$I$4 -> 46136
A5: ลำดับ | B5: วันที่ | C5: เลขที่เอกสาร | D5: หน่วยงาน | E5: สินค้า | F5: จำนวนเที่ยว | I5: หมายเหตุ
F6: 8.00-17.00 | G6: หลัง 17.00 | H6: (คิว)
A7: 1 | B7: ='9'!B7 -> 46107
A8: 2
A9: 3
A10: 4
A11: 5
A12: 6
A13: 7
A14: 8
A15: 9
A16: 10
A17: รวม | F17: =SUM(F7:F16) -> 0 | G17: =SUM(G7:G16) -> 0 | H17: =SUM(H7:H16) -> 0
A18: 1 | B18: =B7+1 -> 46108
A19: 2
A20: 3
A21: 4
A22: 5
A23: 6
A24: 7
A25: 8
A26: 9
A27: 10
A28: รวม | F28: =SUM(F18:F27) -> 0 | G28: =SUM(G18:G27) -> 0 | H28: =SUM(H18:H27) -> 0
A29: 1 | B29: =B18+1 -> 46109
A30: 2
A31: 3
A32: 4
A33: 5
A34: 6
A35: 7
A36: 8
A37: 9
A38: 10
A39: รวม | F39: =SUM(F29:F38) -> 0 | G39: =SUM(G29:G38) -> 0 | H39: =SUM(H29:H38) -> 0
A40: 1 | B40: =B29+1 -> 46110
...

Sheet รถโม่เสริม
A1: บริษัท เอ็นเอ็นวาย แมททีเรียลส์ จำกัด
A2: รายงานการวิ่งรถประจำเดือน | F2: ='1'!$F$2 -> เมษายน | G2: ปี | H2: ='1'!$H$2 -> 2569
A3: เบอร์รถ….... | H3: หน้า | I3: 1
A4: ทะเบียนรถ ….... | E4: ตั้งแต่วันที่ | F4: ='1'!$F$4 -> 46107 | H4: ถึงวันที่ | I4: ='1'!$I$4 -> 46136
A5: ลำดับ | B5: วันที่ | C5: เลขที่เอกสาร | D5: หน่วยงาน | E5: สินค้า | F5: จำนวนเที่ยว | I5: หมายเหตุ
F6: 8.00-17.00 | G6: หลัง 17.00 | H6: (คิว)
A7: 1 | B7: ='10'!B7 -> 46107
A8: 2
A9: 3
A10: 4
A11: 5
A12: 6
A13: 7
A14: 8
A15: 9
A16: 10
A17: รวม | F17: =SUM(F7:F16) -> 0 | G17: =SUM(G7:G16) -> 0 | H17: =SUM(H7:H16) -> 0
A18: 1 | B18: =B7+1 -> 46108
A19: 2
A20: 3
A21: 4
A22: 5
A23: 6
A24: 7
A25: 8
A26: 9
A27: 10
A28: รวม | F28: =SUM(F18:F27) -> 0 | G28: =SUM(G18:G27) -> 0 | H28: =SUM(H18:H27) -> 0
A29: 1 | B29: =B18+1 -> 46109
A30: 2
A31: 3
A32: 4
A33: 5
A34: 6
A35: 7
A36: 8
A37: 9
A38: 10
A39: รวม | F39: =SUM(F29:F38) -> 0 | G39: =SUM(G29:G38) -> 0 | H39: =SUM(H29:H38) -> 0
A40: 1 | B40: =B29+1 -> 46110
...

Sheet Loader
A1: บริษัท เอ็นเอ็นวาย แมททีเรียลส์
A2: รายงานการวิ่งรถประจำเดือน เมษายน ปี 69
A3: รถ…Loader SANY... | D3: หน้า | E3: 1
A4: ทะเบียนรถ - | D4: เดือน | E4: 26/03/69 - 24/04/69
A5: ลำดับ | B5: วันที่ | C5: หน่วยงาน | D5: จำนวน | E5: หมายเหตุ
D6: (คิว)
A7: 1 | B7: ='1'!B7 -> 46107 | C7: เทพื้นภายใน | D7: =E7+E8 -> 311.5
C8: ส่งภายนอก | E8: 311.5
A9: 2 | B9: =B7+1 -> 46108 | C9: เทพื้นภายใน | D9: =E9+E10 -> 516
C10: ส่งภายนอก | E10: 516
A11: 3 | B11: =B9+1 -> 46109 | C11: เทพื้นภายใน | D11: =E11+E12 -> 167.25
C12: ส่งภายนอก | E12: 167.25
A13: 4 | B13: =B11+1 -> 46110 | C13: เทพื้นภายใน | D13: =E13+E14 -> 361.25
C14: ส่งภายนอก | E14: 361.25
A15: 5 | B15: =B13+1 -> 46111 | C15: เทพื้นภายใน | D15: =E15+E16 -> 413.75
C16: ส่งภายนอก | E16: 413.75
A17: 6 | B17: =B15+1 -> 46112 | C17: เทพื้นภายใน | D17: =E17+E18 -> 422.5
C18: ส่งภายนอก | E18: 422.5
A19: 7 | B19: =B17+1 -> 46113 | C19: เทพื้นภายใน | D19: =E19+E20 -> 241
C20: ส่งภายนอก | E20: 241
A21: 8 | B21: =B19+1 -> 46114 | C21: เทพื้นภายใน | D21: =E21+E22 -> 468.25
C22: ส่งภายนอก | E22: 468.25
A23: 9 | B23: =B21+1 -> 46115 | C23: เทพื้นภายใน | D23: =E23+E24 -> 609
C24: ส่งภายนอก | E24: 609
A25: 10 | B25: =B23+1 -> 46116 | C25: เทพื้นภายใน | D25: =E25+E26 -> 217
C26: ส่งภายนอก | E26: 217
A27: 11 | B27: =B25+1 -> 46117 | C27: เทพื้นภายใน | D27: =E27+E28 -> 354.75
C28: ส่งภายนอก | E28: 354.75
A29: 12 | B29: =B27+1 -> 46118 | C29: เทพื้นภายใน | D29: =E29+E30 -> 505.5
C30: ส่งภายนอก | E30: 505.5
A31: 13 | B31: =B29+1 -> 46119 | C31: เทพื้นภายใน | D31: =E31+E32 -> 369.75
C32: ส่งภายนอก | E32: 369.75
A33: 14 | B33: =B31+1 -> 46120 | C33: เทพื้นภายใน | D33: =E33+E34 -> 284
C34: ส่งภายนอก | E34: 284
A35: 15 | B35: =B33+1 -> 46121 | C35: เทพื้นภายใน | D35: =E35+E36 -> 322
C36: ส่งภายนอก | E36: 322
A37: 16 | B37: =B35+1 -> 46122 | C37: เทพื้นภายใน | D37: =E37+E38 -> 318.25
C38: ส่งภายนอก | E38: 318.25
A39: 17 | B39: =B37+1 -> 46123 | C39: เทพื้นภายใน | D39: =E39+E40 -> 251
C40: ส่งภายนอก | E40: 251
...

Sheet รถน้ำ
A1: บริษัท เอ็นเอ็นวาย แมททีเรียลส์
A2: =Loader!A2 -> รายงานการวิ่งรถประจำเดือน เมษายน ปี 69
A3: รถ…รถน้ำ | D3: หน้า | E3: 1
A4: ทะเบียนรถ 54-8957 | D4: เดือน | E4: =Loader!E4 -> 26/03/69 - 24/04/69
A5: ลำดับ | B5: วันที่ | C5: หน่วยงาน | D5: จำนวน | E5: หมายเหตุ
D6: (คิว)
A7: 1 | B7: =Loader!B7 -> 46107 | C7: ใช้ภายในแพล้น | D7: =E7+E8 -> 7 | E7: 7
C8: ส่งภายนอก
A9: 2 | B9: =B7+1 -> 46108 | C9: ใช้ภายในแพล้น | D9: =E9+E10 -> 10 | E9: 10
C10: ส่งภายนอก
A11: 3 | B11: =B9+1 -> 46109 | C11: ใช้ภายในแพล้น | D11: =E11+E12 -> 13 | E11: 13
C12: ส่งภายนอก
A13: 4 | B13: =B11+1 -> 46110 | C13: ใช้ภายในแพล้น | D13: =E13+E14 -> 8 | E13: 8
C14: ส่งภายนอก
A15: 5 | B15: =B13+1 -> 46111 | C15: ใช้ภายในแพล้น | D15: =E15+E16 -> 11 | E15: 11
C16: ส่งภายนอก
A17: 6 | B17: =B15+1 -> 46112 | C17: ใช้ภายในแพล้น | D17: =E17+E18 -> 11 | E17: 11
C18: ส่งภายนอก
A19: 7 | B19: =B17+1 -> 46113 | C19: ใช้ภายในแพล้น | D19: =E19+E20 -> 7 | E19: 7
C20: ส่งภายนอก
A21: 8 | B21: =B19+1 -> 46114 | C21: ใช้ภายในแพล้น | D21: =E21+E22 -> 11 | E21: 11
C22: ส่งภายนอก
A23: 9 | B23: =B21+1 -> 46115 | C23: ใช้ภายในแพล้น | D23: =E23+E24 -> 17 | E23: 17
C24: ส่งภายนอก
A25: 10 | B25: =B23+1 -> 46116 | C25: ใช้ภายในแพล้น | D25: =E25+E26 -> 12 | E25: 12
C26: ส่งภายนอก
A27: 11 | B27: =B25+1 -> 46117 | C27: ใช้ภายในแพล้น | D27: =E27+E28 -> 10 | E27: 10
C28: ส่งภายนอก
A29: 12 | B29: =B27+1 -> 46118 | C29: ใช้ภายในแพล้น | D29: =E29+E30 -> 11 | E29: 11
C30: ส่งภายนอก
A31: 13 | B31: =B29+1 -> 46119 | C31: ใช้ภายในแพล้น | D31: =E31+E32 -> 14 | E31: 14
C32: ส่งภายนอก
A33: 14 | B33: =B31+1 -> 46120 | C33: ใช้ภายในแพล้น | D33: =E33+E34 -> 10 | E33: 10
C34: ส่งภายนอก
A35: 15 | B35: =B33+1 -> 46121 | C35: ใช้ภายในแพล้น | D35: =E35+E36 -> 11 | E35: 11
C36: ส่งภายนอก
A37: 16 | B37: =B35+1 -> 46122 | C37: ใช้ภายในแพล้น | D37: =E37+E38 -> 13 | E37: 13
C38: ส่งภายนอก
A39: 17 | B39: =B37+1 -> 46123 | C39: ใช้ภายในแพล้น | D39: =E39+E40 -> 10 | E39: 10
C40: ส่งภายนอก
...

Sheet เทรลเลอร์1
A1: บริษัท เอ็นเอ็นวาย แมททีเรียลส์
A2: =Loader!A2 -> รายงานการวิ่งรถประจำเดือน เมษายน ปี 69
A3: รถ…รถเทรลเลอรร์หัวลาก | D3: หน้า | E3: 1
A4: ทะเบียนรถ | D4: เดือน | E4: =Loader!E4 -> 26/03/69 - 24/04/69
A5: ลำดับ | B5: วันที่ | C5: หน่วยงาน | D5: จำนวน | E5: หมายเหตุ
D6: (คิว)
A7: 1 | B7: =Loader!B7 -> 46107 | C7: ขนส่งหิน | D7: =E7+E8 -> 3 | E7: 3
C8: ขนส่ง อื่นๆ
A9: 2 | B9: =B7+1 -> 46108 | C9: ขนส่งหิน | D9: =E9+E10 -> 3 | E9: 3
C10: ขนส่ง อื่นๆ
A11: 3 | B11: =B9+1 -> 46109 | C11: ขนส่งหิน | D11: =E11+E12 -> 3 | E11: 3
C12: ขนส่ง อื่นๆ
A13: 4 | B13: =B11+1 -> 46110 | C13: ขนส่งหิน | D13: =E13+E14 -> 2 | E13: 2
C14: ขนส่ง อื่นๆ
A15: 5 | B15: =B13+1 -> 46111 | C15: ขนส่งหิน | D15: =E15+E16 -> 2 | E15: 2
C16: ขนส่ง อื่นๆ
A17: 6 | B17: =B15+1 -> 46112 | C17: ขนส่งหิน | D17: =E17+E18 -> 3 | E17: 3
C18: ขนส่ง อื่นๆ
A19: 7 | B19: =B17+1 -> 46113 | C19: ขนส่งหิน | D19: =E19+E20 -> 2 | E19: 2
C20: ขนส่ง อื่นๆ
A21: 8 | B21: =B19+1 -> 46114 | C21: ขนส่งหิน | D21: =E21+E22 -> 3 | E21: 3
C22: ขนส่ง อื่นๆ
A23: 9 | B23: =B21+1 -> 46115 | C23: ขนส่งหิน | D23: =E23+E24 -> 0
C24: ขนส่ง อื่นๆ
A25: 10 | B25: =B23+1 -> 46116 | C25: ขนส่งหิน | D25: =E25+E26 -> 0
C26: ขนส่ง อื่นๆ
A27: 11 | B27: =B25+1 -> 46117 | C27: ขนส่งหิน | D27: =E27+E28 -> 0
C28: ขนส่ง อื่นๆ
A29: 12 | B29: =B27+1 -> 46118 | C29: ขนส่งหิน | D29: =E29+E30 -> 0
C30: ขนส่ง อื่นๆ
A31: 13 | B31: =B29+1 -> 46119 | C31: ขนส่งหิน | D31: =E31+E32 -> 0
C32: ขนส่ง อื่นๆ
A33: 14 | B33: =B31+1 -> 46120 | C33: ขนส่งหิน | D33: =E33+E34 -> 2 | E33: 2
C34: ขนส่ง อื่นๆ
A35: 15 | B35: =B33+1 -> 46121 | C35: ขนส่งหิน | D35: =E35+E36 -> 1 | E35: 1
C36: ขนส่ง อื่นๆ
A37: 16 | B37: =B35+1 -> 46122 | C37: ขนส่งหิน | D37: =E37+E38 -> 2 | E37: 2
C38: ขนส่ง อื่นๆ
A39: 17 | B39: =B37+1 -> 46123 | C39: ขนส่งหิน | D39: =E39+E40 -> 3 | E39: 3
C40: ขนส่ง อื่นๆ
...

Sheet เทรลเลอร์2
A1: บริษัท เอ็นเอ็นวาย แมททีเรียลส์
A2: =เทรลเลอร์1!A2 -> รายงานการวิ่งรถประจำเดือน เมษายน ปี 69
A3: รถ…รถเทรลเลอรร์หัวลาก | D3: หน้า | E3: 1
A4: ทะเบียนรถ | D4: เดือน | E4: =Loader!E4 -> 26/03/69 - 24/04/69
A5: ลำดับ | B5: วันที่ | C5: หน่วยงาน | D5: จำนวน | E5: หมายเหตุ
D6: (คิว)
A7: 1 | B7: =Loader!B7 -> 46107 | C7: ขนส่งหิน | D7: =E7+E8 -> 0
C8: ขนส่ง อื่นๆ
A9: 2 | B9: =B7+1 -> 46108 | C9: ขนส่งหิน | D9: =E9+E10 -> 0
C10: ขนส่ง อื่นๆ
A11: 3 | B11: =B9+1 -> 46109 | C11: ขนส่งหิน | D11: =E11+E12 -> 0
C12: ขนส่ง อื่นๆ
A13: 4 | B13: =B11+1 -> 46110 | C13: ขนส่งหิน | D13: =E13+E14 -> 0
C14: ขนส่ง อื่นๆ
A15: 5 | B15: =B13+1 -> 46111 | C15: ขนส่งหิน | D15: =E15+E16 -> 0
C16: ขนส่ง อื่นๆ
A17: 6 | B17: =B15+1 -> 46112 | C17: ขนส่งหิน | D17: =E17+E18 -> 0
C18: ขนส่ง อื่นๆ
A19: 7 | B19: =B17+1 -> 46113 | C19: ขนส่งหิน | D19: =E19+E20 -> 0
C20: ขนส่ง อื่นๆ
A21: 8 | B21: =B19+1 -> 46114 | C21: ขนส่งหิน | D21: =E21+E22 -> 0
C22: ขนส่ง อื่นๆ
A23: 9 | B23: =B21+1 -> 46115 | C23: ขนส่งหิน | D23: =E23+E24 -> 3 | E23: 3
C24: ขนส่ง อื่นๆ
A25: 10 | B25: =B23+1 -> 46116 | C25: ขนส่งหิน | D25: =E25+E26 -> 3 | E25: 3
C26: ขนส่ง อื่นๆ
A27: 11 | B27: =B25+1 -> 46117 | C27: ขนส่งหิน | D27: =E27+E28 -> 3 | E27: 3
C28: ขนส่ง อื่นๆ
A29: 12 | B29: =B27+1 -> 46118 | C29: ขนส่งหิน | D29: =E29+E30 -> 2 | E29: 2
C30: ขนส่ง อื่นๆ
A31: 13 | B31: =B29+1 -> 46119 | C31: ขนส่งหิน | D31: =E31+E32 -> 2 | E31: 2
C32: ขนส่ง อื่นๆ
A33: 14 | B33: =B31+1 -> 46120 | C33: ขนส่งหิน | D33: =E33+E34 -> 0
C34: ขนส่ง อื่นๆ
A35: 15 | B35: =B33+1 -> 46121 | C35: ขนส่งหิน | D35: =E35+E36 -> 0
C36: ขนส่ง อื่นๆ
A37: 16 | B37: =B35+1 -> 46122 | C37: ขนส่งหิน | D37: =E37+E38 -> 0
C38: ขนส่ง อื่นๆ
A39: 17 | B39: =B37+1 -> 46123 | C39: ขนส่งหิน | D39: =E39+E40 -> 0
C40: ขนส่ง อื่นๆ
...

Sheet เทรลเลอร์3
A1: บริษัท เอ็นเอ็นวาย แมททีเรียลส์
A2: =เทรลเลอร์1!A2 -> รายงานการวิ่งรถประจำเดือน เมษายน ปี 69
A3: รถ…รถเทรลเลอรร์หัวลาก | D3: หน้า | E3: 1
A4: ทะเบียนรถ | D4: เดือน | E4: =Loader!E4 -> 26/03/69 - 24/04/69
A5: ลำดับ | B5: วันที่ | C5: หน่วยงาน | D5: จำนวน | E5: หมายเหตุ
D6: (คิว)
A7: 1 | B7: =Loader!B7 -> 46107 | C7: ขนส่งหิน | D7: =E7+E8 -> 0
C8: ขนส่ง อื่นๆ
A9: 2 | B9: =B7+1 -> 46108 | C9: ขนส่งหิน | D9: =E9+E10 -> 0
C10: ขนส่ง อื่นๆ
A11: 3 | B11: =B9+1 -> 46109 | C11: ขนส่งหิน | D11: =E11+E12 -> 0
C12: ขนส่ง อื่นๆ
A13: 4 | B13: =B11+1 -> 46110 | C13: ขนส่งหิน | D13: =E13+E14 -> 0
C14: ขนส่ง อื่นๆ
A15: 5 | B15: =B13+1 -> 46111 | C15: ขนส่งหิน | D15: =E15+E16 -> 0
C16: ขนส่ง อื่นๆ
A17: 6 | B17: =B15+1 -> 46112 | C17: ขนส่งหิน | D17: =E17+E18 -> 0
C18: ขนส่ง อื่นๆ
A19: 7 | B19: =B17+1 -> 46113 | C19: ขนส่งหิน | D19: =E19+E20 -> 0
C20: ขนส่ง อื่นๆ
A21: 8 | B21: =B19+1 -> 46114 | C21: ขนส่งหิน | D21: =E21+E22 -> 0
C22: ขนส่ง อื่นๆ
A23: 9 | B23: =B21+1 -> 46115 | C23: ขนส่งหิน | D23: =E23+E24 -> 0
C24: ขนส่ง อื่นๆ
A25: 10 | B25: =B23+1 -> 46116 | C25: ขนส่งหิน | D25: =E25+E26 -> 0
C26: ขนส่ง อื่นๆ
A27: 11 | B27: =B25+1 -> 46117 | C27: ขนส่งหิน | D27: =E27+E28 -> 0
C28: ขนส่ง อื่นๆ
A29: 12 | B29: =B27+1 -> 46118 | C29: ขนส่งหิน | D29: =E29+E30 -> 0
C30: ขนส่ง อื่นๆ
A31: 13 | B31: =B29+1 -> 46119 | C31: ขนส่งหิน | D31: =E31+E32 -> 0
C32: ขนส่ง อื่นๆ
A33: 14 | B33: =B31+1 -> 46120 | C33: ขนส่งหิน | D33: =E33+E34 -> 0
C34: ขนส่ง อื่นๆ
A35: 15 | B35: =B33+1 -> 46121 | C35: ขนส่งหิน | D35: =E35+E36 -> 0
C36: ขนส่ง อื่นๆ
A37: 16 | B37: =B35+1 -> 46122 | C37: ขนส่งหิน | D37: =E37+E38 -> 0
C38: ขนส่ง อื่นๆ
A39: 17 | B39: =B37+1 -> 46123 | C39: ขนส่งหิน | D39: =E39+E40 -> 0
C40: ขนส่ง อื่นๆ
...

Sheet เซลล์ (งานเครดิต)
A1: บริษัท เอ็นเอ็นวาย แมททีเรียลส์ จำกัด
A2: รายงานการสรุปยอดขายของพนักงานขายประจำเดือน เมษายน ปี 2569
A3: พนักงานขาย นายอำนาจ ชัยประภา | G3: หน้า | H3: 1
F4: ='1'!F4:G4 -> 46107 | G4: ถึงวันที่ | H4: ='1'!I4 -> 46136
A5: ลำดับ | B5: วันที่ | C5: เลขที่เอกสาร | D5: ลูกค้า | E5: หน่วยงาน | F5: สินค้า | G5: จำนวน | H5: หมายเหตุ
G6: (คิว)
A7: 1 | B7: =รถน้ำ!B7:B8 -> 46107 | D7: บจก.หู่เฟิง เอ็นจิเนียริ่ง | E7: โครงการ Joinehands 4 ซอย 6 สาย 11 | F7: N0000NP00 | G7: 2
A8: 2 | D8: บจก.หู่เฟิง เอ็นจิเนียริ่ง | E8: โครงการ Joinehands 4 ซอย 6 สาย 11 | F8: N3200NP00A | G8: 5
A9: 3 | D9: บจก จิงกง คอนสตรัคชั่น (ประเทศไทย) จำกัด | E9: Thaiya | F9: N1800NP00A | G9: 11
A10: 4 | D10: บจก จิงกง คอนสตรัคชั่น (ประเทศไทย) จำกัด | E10: Thaiya | F10: N2800NP00A | G10: 3
A11: 5 | D11: บริษัท โหลงไท่อินเตอร์เนชั่นแนล จำกัด | E11: โรงงาน FIN เฟส 2 | F11: N3200NP00A | G11: 12.5
A12: 6 | D12: บจก.เอ็นวี นิว วิชั่น | E12: สร้างโรงงานซอย 13 | F12: N3200NP00A | G12: 72
A13: 7
A14: รวม | G14: =SUM(G7:G13) -> 105.5
A15: 1 | B15: =B7+1 -> 46108 | D15: บจก.หู่เฟิง เอ็นจิเนียริ่ง | E15: โครงการ Joinehands 4 ซอย 6 สาย 11 | F15: N0000NP00 | G15: 2
A16: 2 | D16: บจก.หู่เฟิง เอ็นจิเนียริ่ง | E16: โครงการ Joinehands 4 ซอย 6 สาย 11 | F16: N3200NP00A | G16: 5
A17: 3 | D17: บจก จิงกง คอนสตรัคชั่น (ประเทศไทย) จำกัด | E17: Thaiya | F17: N3200NP00A | G17: 10
A18: 4 | D18: บจก.เซล คอนสตรัคชั่น แอนด์ ดีเวลลอปเมนท์ กรุ๊ป | E18: โครงการ TECHSTRONG ซอย 7 | F18: N0000NP05 | G18: 1
A19: 5 | D19: บจก.เซล คอนสตรัคชั่น แอนด์ ดีเวลลอปเมนท์ กรุ๊ป | E19: โครงการ TECHSTRONG ซอย 7 | F19: N3201NP01A | G19: 172
A20: 6 | D20: บริษัท โหลงไท่อินเตอร์เนชั่นแนล จำกัด | E20: โครงการนิวเทรนด์ ฟู๊ด เฟส 2 | F20: N0000NP05 | G20: 10
A21: 7 | D21: บริษัท โหลงไท่อินเตอร์เนชั่นแนล จำกัด | E21: โครงการนิวเทรนด์ ฟู๊ด เฟส 2 | F21: N3201NP01A | G21: 1.5
A22: 8 | D22: บจก สุขนภา 2025 | E22: ซอย 14 สาย 13 | F22: N2400NP00A | G22: 22
A23: 9 | D23: บจก.เอ็นวี นิว วิชั่น | E23: สร้างโรงงานซอย 13 | F23: N2400NP00A | G23: 4
A24: รวม | G24: =SUM(G15:G23) -> 227.5
A25: 1 | B25: =B15+1 -> 46109 | D25: บจก.วิธา | E25: โครงการวาเลย์ เฮาส์ | F25: N2400NP00A | G25: 9.5
A26: 2
A27: 3
A28: 4
A29: 5
A30: 6
A31: 7
A32: รวม | G32: =SUM(G25:G31) -> 9.5
A33: 1 | B33: =B25+1 -> 46110 | D33: บจก.หู่เฟิง เอ็นจิเนียริ่ง | E33: โครงการ Joinehands 4 ซอย 6 สาย 11 | F33: N0000NP00 | G33: 15
A34: 2 | D34: บจก.หู่เฟิง เอ็นจิเนียริ่ง | E34: โครงการ Joinehands 4 ซอย 6 สาย 11 | F34: N3200NP00A | G34: 8
A35: 3 | D35: บจก จิงกง คอนสตรัคชั่น (ประเทศไทย) จำกัด | E35: Thaiya | F35: N3200NP00A | G35: 10
A36: 4 | D36: บจก.เซล คอนสตรัคชั่น แอนด์ ดีเวลลอปเมนท์ กรุ๊ป | E36: โครงการ TECHSTRONG ซอย 7 | F36: N0000NP05 | G36: 1
A37: 5 | D37: บจก.เซล คอนสตรัคชั่น แอนด์ ดีเวลลอปเมนท์ กรุ๊ป | E37: โครงการ TECHSTRONG ซอย 7 | F37: N3201NP01A | G37: 174.5
A38: 6 | D38: บริษัท โหลงไท่อินเตอร์เนชั่นแนล จำกัด | E38: โครงการนิวเทรนด์ ฟู๊ด เฟส 2 | F38: N3201NP01A | G38: 18
A39: 7
A40: รวม | G40: =SUM(G33:G39) -> 226.5
...

Sheet เซลล์ (งานเงินสด)
A1: บริษัท เอ็นเอ็นวาย แมททีเรียลส์ จำกัด
A2: ='เซลล์ (งานเครดิต)'!A2:H2 -> รายงานการสรุปยอดขายของพนักงานขายประจำเดือน เมษายน ปี 2569
A3: พนักงานขาย นายอำนาจ ชัยประภา | G3: หน้า | H3: 1
F4: ='เซลล์ (งานเครดิต)'!F4 -> 46107 | G4: ถึงวันที่ | H4: ='เซลล์ (งานเครดิต)'!H4 -> 46136
A5: ลำดับ | B5: วันที่ | C5: เลขที่เอกสาร | D5: ลูกค้า | E5: หน่วยงาน | F5: สินค้า | G5: จำนวน | H5: หมายเหตุ
G6: (คิว)
A7: 1 | B7: ='เซลล์ (งานเครดิต)'!B7 -> 46107 | D7: คุณธนกร ศรีพุทธา | E7: ซอย 14 สาย 15 | F7: N3000NP00A | G7: 5.5
A8: 2 | D8: บจก.เอ็นที พร็อพเพอร์ตี้ 2021 | E8: โครงการ ซอย 12 สาย 15 (ร้านกาแฟ) | F8: N2400NP00A | G8: 4
A9: 3 | D9: คุณกวิน อ้นขวัญเมือง | E9: ซอย 8 สาย 15 | F9: N2400NP00A | G9: 3
A10: 4 | D10: บจก.หอพักสาย19 เพลส | E10: อพาร์ทเม้นท์ซอย 13 สาย 19 | F10: N3201NP01A | G10: 5
A11: 5
A12: 6
A13: 7
A14: 8
A15: 9
A16: รวม | G16: =SUM(G7:G15) -> 17.5
A17: 1 | B17: =B7+1 -> 46108 | D17: บจก.ชัชนา พร็อพเพอร์ตี้ | E17: โครงการซอย 13 สาย 11 | F17: N2400NP00A | G17: 16
A18: 2 | D18: หจก.นัชชา คอนสตรัคชั่น | E18: สร้างห้องเช่า ซอย 13 สาย 19 | F18: N2400NP00A | G18: 15
A19: 3
A20: 4
A21: 5
A22: 6
A23: 7
A24: 8
A25: รวม | G25: =SUM(G17:G24) -> 31
A26: 1 | B26: =B17+1 -> 46109 | D26: บจก.ช.วิรัตน์ รุ่งเรืองก่อสร้าง | E26: โครงการ ซอย 12 สาย 15 (หมู่บ้านอุดมสุข) | F26: N2400NP00A | G26: 3
A27: 2 | D27: บจก.ชัชนา พร็อพเพอร์ตี้ | E27: โครงการซอย 13 สาย 11 | F27: N2400NP00A | G27: 16
A28: 3 | D28: บจก.ช.วิรัตน์ รุ่งเรืองก่อสร้าง | E28: ตลาดเช้าซอย 13 สาย 13 | F28: N2400NP00A | G28: 4
A29: 4 | D29: บจก.หลู่ไท่ คอนสตรั๊คชั่น | E29: โรงงาน คิวไทย CPGC | F29: N3200NP00A | G29: 30.5
A30: 5 | D30: บจก.หลู่ไท่ คอนสตรั๊คชั่น | E30: โรงงานเกมบอลอมตะซิตี้ | F30: N3200NP00A | G30: 2.5
A31: 6 | D31: บจก.ปิยะมณี แลนด์แอนด์เฮ้าส์ | E31: สร้างโกดังซอย 6 สาย 13 | F31: N3000NP00A | G31: 16.5
A32: 7 | D32: หจก.นัชชา คอนสตรัคชั่น | E32: สร้างห้องเช่า ซอย 13 สาย 19 | F32: N2400NP00A | G32: 21.5
A33: 8 | D33: บจก.ไทย สตีล คอนสตรัคเจอร์ คอนสตรัคชั่น | E33: สร้างออฟฟิศแคมป์คนงานซอย 13 สาย 19 | F33: N1800NP00A | G33: 6
A34: 9 | D34: บจก.ไทย สตีล คอนสตรัคเจอร์ คอนสตรัคชั่น | E34: สร้างออฟฟิศแคมป์คนงานซอย 13 สาย 19 | F34: N3200NP00A | G34: 27
A35: 10
A36: รวม | G36: =SUM(G26:G35) -> 127
A37: 1 | B37: =B26+1 -> 46110 | D37: คุณธนกร ศรีพุทธา | E37: ซอย 12 สาย 15 | F37: N3000NP00A | G37: 2.5
A38: 2 | D38: คุณสุมาลี ปัญญาคำ | E38: ซอย 12 สาย 19 (คุณสุมาลี) | F38: N2400NP00A | G38: 3
A39: 3 | D39: คุณวสันต์ สันลี | E39: ซอย 3 | F39: N2400NP00A | G39: 4.5
A40: 4 | D40: บจก.หงส์อัน เอ็นจิเนียริ่ง | E40: โรงงานอะซิมโคนิคมอมตะซิตี้ | F40: N3200NP00A | G40: 105.5
...

Sheet สรุปค่าเที่ยวค่าคิว
A1: บริษัท เอ็นเอ็นวาย แมททีเรียลส์ จำกัด
A2: รายงานสรุปค่าเที่ยวรถมิกซ์ ประจำเดือน เมษายน 2569
A4: รหัสพนักงาน | B4: ชื่อ-สกุล | C4: เวลา | D4: ตั้งแต่วันที่ …26.../….03..../…69.... ถึงวันที่ …24..../…04..../…69.... | AM4: รวมเที่ยว | AN4: 80 | AO4: หลัง 17.00@100 | AP4: รวมค่าเที่ยว,ค่าคิว | AQ4: ค่าทำความสะอาดรถ | AR4: Total
D5: วันที่
D6: 26 | E6: 27 | F6: 28 | G6: 29 | H6: 30 | I6: 31 | J6: 1 | K6: 2 | L6: 3 | M6: 4 | N6: 5 | O6: 6 | P6: 7 | Q6: 8 | R6: 9 | S6: 10 | T6: 11 | U6: 12 | V6: 13 | W6: 14 | X6: 15 | Y6: 16 | Z6: 17 | AA6: 18 | AB6: 19 | AC6: 20 | AD6: 21 | AE6: 22 | AF6: 23 | AG6: 24 | AN6: รวมเป็นเงิน | AO6: รวมเป็นเงิน
A7: 67134 | B7: นายสราวุฒิ โพธิ์กระสัง | C7: 8.00-17.00 | D7: ='1'!$F$17 -> 5 | E7: ='1'!$F$28 -> 5 | F7: ='1'!$F$39 -> 4 | G7: ='1'!$F$50 -> 0 | H7: ='1'!$F$61 -> 6 | I7: ='1'!$F$72 -> 6 | J7: ='1'!$F$83 -> 4 | K7: ='1'!$F$101 -> 7 | L7: ='1'!$F$112 -> 6 | M7: ='1'!$F$123 -> 4 | N7: ='1'!$F$134 -> 5 | O7: ='1'!$F$145 -> 4 | P7: ='1'!$F$156 -> 6 | Q7: ='1'!$F$167 -> 0 | R7: ='1'!$F$185 -> 0 | S7: ='1'!$F$196 -> 2 | T7: ='1'!$F$207 -> 0 | U7: ='1'!$F$218 -> 0 | V7: ='1'!$F$229 -> 0 | W7: ='1'!$F$240 -> 0 | X7: ='1'!$F$251 -> 0 | Y7: ='1'!$F$269 -> 0 | Z7: ='1'!$F$280 -> 0 | AA7: ='1'!$F$291 -> 0 | AB7: ='1'!$F$302 -> 0 | AC7: ='1'!$F$313 -> 0 | AD7: ='1'!$F$324 -> 5 | AE7: ='1'!$F$335 -> 4 | AF7: ='1'!$F$353 -> 5 | AG7: ='1'!$F$364 -> 5 | AH7: ='1'!$F$375 -> 0 | AI7: ='1'!$F$386 -> 0 | AJ7: ='1'!$F$397 -> 0 | AK7: ='1'!$F$408 -> 0 | AL7: ='1'!$F$419 -> 0 | AM7: =SUM(D7:AL7) -> 83 | AN7: =AM7*$AN$4 -> 6640 | AP7: =SUM(AN7:AO8) -> 9140 | AQ7: 900 | AR7: =SUM(AP7:AQ8) -> 10040
A8: ทะเบียน | B8: 53-0601 (1) | C8: หลัง 17.00 | D8: ='1'!$G$17 -> 1 | E8: ='1'!$G$28 -> 3 | F8: ='1'!$G$39 -> 0 | G8: ='1'!$G$50 -> 0 | H8: ='1'!$G$61 -> 1 | I8: ='1'!$G$72 -> 1 | J8: ='1'!$G$83 -> 1 | K8: ='1'!$G$101 -> 2 | L8: ='1'!$G$112 -> 3 | M8: ='1'!$G$123 -> 0 | N8: ='1'!$G$134 -> 1 | O8: ='1'!$G$145 -> 4 | P8: ='1'!$G$156 -> 0 | Q8: ='1'!$G$167 -> 0 | R8: ='1'!$G$185 -> 0 | S8: ='1'!$G$196 -> 2 | T8: ='1'!$G$207 -> 0 | U8: ='1'!$G$218 -> 0 | V8: ='1'!$G$229 -> 0 | W8: ='1'!$G$240 -> 0 | X8: ='1'!$G$251 -> 0 | Y8: ='1'!$G$269 -> 0 | Z8: ='1'!$G$280 -> 0 | AA8: ='1'!$G$291 -> 0 | AB8: ='1'!$G$302 -> 0 | AC8: ='1'!$G$313 -> 0 | AD8: ='1'!$G$324 -> 3 | AE8: ='1'!$G$335 -> 0 | AF8: ='1'!$G$353 -> 1 | AG8: ='1'!$G$364 -> 2 | AH8: ='1'!$G$375 -> 0 | AI8: ='1'!$G$386 -> 0 | AJ8: ='1'!$G$397 -> 0 | AK8: ='1'!$G$408 -> 0 | AL8: ='1'!$G$419 -> 0 | AM8: =SUM(D8:AL8) -> 25 | AO8: =AM8*100 -> 2500
A9: 67163 | B9: นายนิรันดร์ สิมสีดา | C9: 8.00-17.00 | D9: ='2'!$F$17 -> 3 | E9: ='2'!$F$28 -> 0 | F9: ='2'!$F$39 -> 3 | G9: ='2'!$F$50 -> 6 | H9: ='2'!$F$61 -> 6 | I9: ='2'!$F$72 -> 2 | J9: ='2'!$F$83 -> 3 | K9: ='2'!$F$101 -> 7 | L9: ='2'!$F$112 -> 4 | M9: ='2'!$F$123 -> 0 | N9: ='2'!$F$134 -> 5 | O9: ='2'!$F$145 -> 3 | P9: ='2'!$F$156 -> 5 | Q9: ='2'!$F$167 -> 4 | R9: ='2'!$F$185 -> 0 | S9: ='2'!$F$196 -> 3 | T9: ='2'!$F$207 -> 3 | U9: ='2'!$F$218 -> 0 | V9: ='2'!$F$229 -> 0 | W9: ='2'!$F$240 -> 0 | X9: ='2'!$F$251 -> 0 | Y9: ='2'!$F$269 -> 0 | Z9: ='2'!$F$280 -> 0 | AA9: ='2'!$F$291 -> 0 | AB9: ='2'!$F$302 -> 0 | AC9: ='2'!$F$313 -> 0 | AD9: ='2'!$F$324 -> 0 | AE9: ='2'!$F$335 -> 0 | AF9: ='2'!$F$353 -> 0 | AG9: ='2'!$F$364 -> 0 | AH9: ='2'!$F$375 -> 0 | AI9: ='2'!$F$386 -> 0 | AJ9: ='2'!$F$397 -> 0 | AK9: ='2'!$F$408 -> 0 | AL9: ='2'!$F$419 -> 0 | AM9: =SUM(D9:AL9) -> 57 | AN9: =AM9*$AN$4 -> 4560 | AP9: =SUM(AN9:AO10) -> 6000 | AQ9: 0 | AR9: =SUM(AP9:AQ10) -> 6000
A10: ทะเบียน | B10: 53-0602 (2) | C10: หลัง 17.00 | D10: ='2'!$G$17 -> 0 | E10: ='2'!$G$28 -> 0 | F10: ='2'!$G$39 -> 0 | G10: ='2'!$G$50 -> 1 | H10: ='2'!$G$61 -> 1 | I10: ='2'!$G$72 -> 0 | J10: ='2'!$G$83 -> 1 | K10: ='2'!$G$101 -> 2 | L10: ='2'!$G$112 -> 3 | M10: ='2'!$G$123 -> 0 | N10: ='2'!$G$134 -> 1 | O10: ='2'!$G$145 -> 4 | P10: ='2'!$G$156 -> 0 | Q10: ='2'!$G$167 -> 0 | R10: ='2'!$G$185 -> 0 | S10: ='2'!$G$196 -> 1 | T10: ='2'!$G$207 -> 0 | U10: ='2'!$G$218 -> 0 | V10: ='2'!$G$229 -> 0 | W10: ='2'!$G$240 -> 0 | X10: ='2'!$G$251 -> 0 | Y10: ='2'!$G$269 -> 0 | Z10: ='2'!$G$280 -> 0 | AA10: ='2'!$G$291 -> 0 | AB10: ='2'!$G$302 -> 0 | AC10: ='2'!$G$313 -> 0 | AD10: ='2'!$G$324 -> 0 | AE10: ='2'!$G$335 -> 0 | AF10: ='2'!$G$353 -> 0 | AG10: ='2'!$G$364 -> 0 | AH10: ='2'!$G$375 -> 0 | AI10: ='2'!$G$386 -> 0 | AJ10: ='2'!$G$397 -> 0 | AK10: ='2'!$G$408 -> 0 | AL10: ='2'!$G$419 -> 0 | AM10: =SUM(D10:AL10) -> 14 | AN10: 40 | AO10: =AM10*100 -> 1400
A11: 66131 | B11: นายประเสิม พร้อมพรั่ง | C11: 8.00-17.00 | D11: ='3'!$F$17 -> 6 | E11: ='3'!$F$28 -> 5 | F11: ='3'!$F$39 -> 2 | G11: ='3'!$F$50 -> 6 | H11: ='3'!$F$61 -> 0 | I11: ='3'!$F$72 -> 6 | J11: ='3'!$F$83 -> 3 | K11: ='3'!$F$101 -> 6 | L11: ='3'!$F$112 -> 6 | M11: ='3'!$F$123 -> 4 | N11: ='3'!$F$134 -> 0 | O11: ='3'!$F$145 -> 4 | P11: ='3'!$F$156 -> 4 | Q11: ='3'!$F$167 -> 5 | R11: ='3'!$F$185 -> 6 | S11: ='3'!$F$196 -> 3 | T11: ='3'!$F$207 -> 4 | U11: ='3'!$F$218 -> 0 | V11: ='3'!$F$229 -> 0 | W11: ='3'!$F$240 -> 0 | X11: ='3'!$F$251 -> 0 | Y11: ='3'!F269 -> 0 | Z11: ='3'!F280 -> 0 | AA11: ='3'!F291 -> 1 | AB11: ='3'!F302 -> 1 | AC11: ='3'!F313 -> 8 | AD11: ='3'!F324 -> 5 | AE11: ='3'!F335 -> 4 | AF11: ='3'!F353 -> 4 | AG11: ='3'!F364 -> 6 | AH11: ='3'!F375 -> 0 | AI11: ='3'!$F$386 -> 0 | AJ11: ='3'!$F$397 -> 0 | AK11: ='3'!$F$408 -> 0 | AL11: ='3'!$F$419 -> 0 | AM11: =SUM(D11:AL11) -> 99 | AN11: =AM11*$AN$4 -> 7920 | AP11: =SUM(AN11:AO12) -> 10260 | AQ11: 900 | AR11: =SUM(AP11:AQ12) -> 11160
A12: ทะเบียน | B12: 53-0603 (3) | C12: หลัง 17.00 | D12: ='3'!G17 -> 0 | E12: ='3'!$G$28 -> 3 | F12: ='3'!$G$39 -> 1 | G12: ='3'!$G$50 -> 0 | H12: ='3'!$G$61 -> 0 | I12: ='3'!$G$72 -> 1 | J12: ='3'!$G$83 -> 1 | K12: ='3'!$G$101 -> 2 | L12: ='3'!$G$112 -> 2 | M12: ='3'!$G$123 -> 1 | N12: ='3'!$G$134 -> 0 | O12: ='3'!$G$145 -> 4 | P12: ='3'!$G$156 -> 1 | Q12: ='3'!$G$167 -> 0 | R12: ='3'!$G$185 -> 0 | S12: ='3'!$G$196 -> 2 | T12: ='3'!$G$207 -> 0 | U12: ='3'!$G$218 -> 0 | V12: ='3'!$G$229 -> 0 | W12: ='3'!$G$240 -> 0 | X12: ='3'!$G$251 -> 0 | Y12: ='3'!G269 -> 0 | Z12: ='3'!G280 -> 0 | AA12: ='3'!G291 -> 0 | AB12: ='3'!G302 -> 0 | AC12: ='3'!G313 -> 0 | AD12: ='3'!G324 -> 2 | AE12: ='3'!G335 -> 0 | AF12: ='3'!G353 -> 2 | AG12: ='3'!G364 -> 1 | AH12: ='3'!G375 -> 0 | AI12: ='3'!$G$386 -> 0 | AJ12: ='3'!$G$397 -> 0 | AK12: ='3'!$G$408 -> 0 | AL12: ='3'!$G$419 -> 0 | AM12: =SUM(D12:AL12) -> 23 | AN12: 40 | AO12: =AM12*100 -> 2300
A13: 63068 | B13: นายชัยวัฒน์ ผดุงเวียง | C13: 8.00-17.00 | D13: ='4'!$F$17 -> 4 | E13: ='4'!$F$28 -> 5 | F13: ='4'!$F$39 -> 3 | G13: ='4'!$F$50 -> 6 | H13: ='4'!$F$61 -> 7 | I13: ='4'!$F$72 -> 6 | J13: ='4'!$F$83 -> 5 | K13: ='4'!$F$101 -> 6 | L13: ='4'!$F$112 -> 6 | M13: ='4'!$F$123 -> 3 | N13: ='4'!$F$134 -> 0 | O13: ='4'!$F$145 -> 4 | P13: ='4'!$F$156 -> 4 | Q13: ='4'!$F$167 -> 5 | R13: ='4'!$F$185 -> 4 | S13: ='4'!$F$196 -> 3 | T13: ='4'!$F$207 -> 4 | U13: ='4'!$F$218 -> 0 | V13: ='4'!$F$229 -> 0 | W13: ='4'!$F$240 -> 0 | X13: ='4'!$F$251 -> 0 | Y13: ='4'!$F$269 -> 0 | Z13: ='4'!$F$280 -> 0 | AA13: ='4'!$F$291 -> 1 | AB13: ='4'!$F$302 -> 1 | AC13: ='4'!$F$313 -> 7 | AD13: ='4'!$F$324 -> 4 | AE13: ='4'!$F$335 -> 4 | AF13: ='4'!$F$353 -> 5 | AG13: ='4'!$F$364 -> 7 | AH13: ='4'!$F$375 -> 0 | AI13: ='4'!$F$386 -> 0 | AJ13: ='4'!$F$397 -> 0 | AK13: ='4'!$F$408 -> 0 | AL13: ='4'!$F$419 -> 0 | AM13: =SUM(D13:AL13) -> 104 | AN13: =AM13*$AN$4 -> 8320 | AP13: =SUM(AN13:AO14) -> 10320 | AQ13: 900 | AR13: =SUM(AP13:AQ14) -> 11220
A14: ทะเบียน | B14: 53-0604 (4) | C14: หลัง 17.00 | D14: ='4'!$G$17 -> 0 | E14: ='4'!$G$28 -> 2 | F14: ='4'!$G$39 -> 0 | G14: ='4'!$G$50 -> 1 | H14: ='4'!$G$61 -> 1 | I14: ='4'!$G$72 -> 0 | J14: ='4'!$G$83 -> 0 | K14: ='4'!$G$101 -> 2 | L14: ='4'!$G$112 -> 3 | M14: ='4'!$G$123 -> 0 | N14: ='4'!$G$134 -> 0 | O14: ='4'!$G$145 -> 4 | P14: ='4'!$G$156 -> 0 | Q14: ='4'!$G$167 -> 0 | R14: ='4'!$G$185 -> 0 | S14: ='4'!$G$196 -> 2 | T14: ='4'!$G$207 -> 0 | U14: ='4'!$G$218 -> 0 | V14: ='4'!$G$229 -> 0 | W14: ='4'!$G$240 -> 0 | X14: ='4'!$G$251 -> 0 | Y14: ='4'!$G$269 -> 0 | Z14: ='4'!$G$280 -> 0 | AA14: ='4'!$G$291 -> 0 | AB14: ='4'!$G$302 -> 0 | AC14: ='4'!$G$313 -> 1 | AD14: ='4'!$G$324 -> 2 | AE14: ='4'!$G$335 -> 0 | AF14: ='4'!$G$353 -> 1 | AG14: ='4'!$G$364 -> 1 | AH14: ='4'!$G$375 -> 0 | AI14: ='4'!$G$386 -> 0 | AJ14: ='4'!$G$397 -> 0 | AK14: ='4'!$G$408 -> 0 | AL14: ='4'!$G$419 -> 0 | AM14: =SUM(D14:AL14) -> 20 | AO14: =AM14*100 -> 2000
A15: 68029 | B15: นายพรชัย วิจารณ์ | C15: 8.00-17.00 | D15: ='5'!$F$17 -> 5 | E15: ='5'!$F$28 -> 6 | F15: ='5'!$F$39 -> 3 | G15: ='5'!$F$50 -> 5 | H15: ='5'!$F$61 -> 6 | I15: ='5'!$F$72 -> 1 | J15: ='5'!$F$83 -> 3 | K15: ='5'!$F$101 -> 5 | L15: ='5'!$F$112 -> 4 | M15: ='5'!$F$123 -> 4 | N15: ='5'!$F$134 -> 5 | O15: ='5'!$F$145 -> 4 | P15: ='5'!$F$156 -> 6 | Q15: ='5'!$F$167 -> 5 | R15: ='5'!$F$185 -> 4 | S15: ='5'!$F$196 -> 2 | T15: ='5'!$F$207 -> 4 | U15: ='5'!$F$218 -> 0 | V15: ='5'!$F$229 -> 0 | W15: ='5'!$F$240 -> 0 | X15: ='5'!$F$251 -> 0 | Y15: ='5'!$F$269 -> 0 | Z15: ='5'!$F$280 -> 0 | AA15: ='5'!$F$291 -> 0 | AB15: ='5'!$F$302 -> 2 | AC15: ='5'!$F$313 -> 6 | AD15: ='5'!$F$324 -> 5 | AE15: ='5'!$F$335 -> 4 | AF15: ='5'!$F$353 -> 4 | AG15: ='5'!$F$364 -> 7 | AH15: ='5'!$F$375 -> 0 | AI15: ='5'!$F$386 -> 0 | AJ15: ='5'!$F$397 -> 0 | AK15: ='5'!$F$408 -> 0 | AL15: ='5'!$F$419 -> 0 | AM15: =SUM(D15:AL15) -> 100 | AN15: =AM15*$AN$4 -> 8000 | AP15: =SUM(AN15:AO16) -> 10100 | AQ15: 900 | AR15: =SUM(AP15:AQ16) -> 11000
A16: ทะเบียน | B16: 53-0605 (5) | C16: หลัง 17.00 | D16: ='5'!$G$17 -> 0 | E16: ='5'!$G$28 -> 1 | F16: ='5'!$G$39 -> 0 | G16: ='5'!$G$50 -> 1 | H16: ='5'!$G$61 -> 0 | I16: ='5'!$G$72 -> 2 | J16: ='5'!$G$83 -> 0 | K16: ='5'!$G$101 -> 2 | L16: ='5'!$G$112 -> 3 | M16: ='5'!$G$123 -> 0 | N16: ='5'!$G$134 -> 1 | O16: ='5'!$G$145 -> 3 | P16: ='5'!$G$156 -> 0 | Q16: ='5'!$G$167 -> 0 | R16: ='5'!$G$185 -> 1 | S16: ='5'!$G$196 -> 2 | T16: ='5'!$G$207 -> 0 | U16: ='5'!$G$218 -> 0 | V16: ='5'!$G$229 -> 0 | W16: ='5'!$G$240 -> 0 | X16: ='5'!$G$251 -> 0 | Y16: ='5'!$G$269 -> 0 | Z16: ='5'!$G$280 -> 0 | AA16: ='5'!$G$291 -> 0 | AB16: ='5'!$G$302 -> 0 | AC16: ='5'!$G$313 -> 1 | AD16: ='5'!$G$324 -> 2 | AE16: ='5'!$G$335 -> 0 | AF16: ='5'!$G$353 -> 2 | AG16: ='5'!$G$364 -> 0 | AH16: ='5'!$G$375 -> 0 | AI16: ='5'!$G$386 -> 0 | AJ16: ='5'!$G$397 -> 0 | AK16: ='5'!$G$408 -> 0 | AL16: ='5'!$G$419 -> 0 | AM16: =SUM(D16:AL16) -> 21 | AO16: =AM16*100 -> 2100
A17: 68031 | B17: นายสุทิล ชูเกณฑ์ | C17: 8.00-17.00 | D17: ='6'!$F$17 -> 0 | E17: ='6'!$F$28 -> 5 | F17: ='6'!$F$39 -> 3 | G17: ='6'!$F$50 -> 5 | H17: ='6'!$F$61 -> 5 | I17: ='6'!$F$72 -> 6 | J17: ='6'!$F$83 -> 4 | K17: ='6'!$F$101 -> 0 | L17: ='6'!$F$112 -> 6 | M17: ='6'!$F$123 -> 3 | N17: ='6'!$F$134 -> 4 | O17: ='6'!$F$145 -> 4 | P17: ='6'!$F$156 -> 5 | Q17: ='6'!$F$167 -> 6 | R17: ='6'!$F$185 -> 6 | S17: ='6'!$F$196 -> 0 | T17: ='6'!$F$207 -> 4 | U17: ='6'!$F$218 -> 0 | V17: ='6'!$F$229 -> 0 | W17: ='6'!$F$240 -> 0 | X17: ='6'!$F$251 -> 0 | Y17: ='6'!$F$269 -> 0 | Z17: ='6'!$F$280 -> 0 | AA17: ='6'!$F$291 -> 0 | AB17: ='6'!$F$302 -> 1 | AC17: ='6'!$F$314 -> 8 | AD17: ='6'!$F$325 -> 5 | AE17: ='6'!$F$336 -> 3 | AF17: ='6'!$F$354 -> 5 | AG17: ='6'!$F$365 -> 6 | AH17: ='6'!$F$376 -> 0 | AI17: ='6'!$F$386 -> 0 | AJ17: ='6'!$F$397 -> 0 | AK17: ='6'!$F$408 -> 0 | AL17: ='6'!$F$419 -> 0 | AM17: =SUM(D17:AL17) -> 94 | AN17: =AM17*$AN$4 -> 7520 | AP17: =SUM(AN17:AO18) -> 9320 | AQ17: 900 | AR17: =SUM(AP17:AQ18) -> 10220
A18: ทะเบียน | B18: 53-0606 (6) | C18: หลัง 17.00 | D18: ='6'!$G$17 -> 0 | E18: ='6'!$G$28 -> 2 | F18: ='6'!$G$39 -> 0 | G18: ='6'!$G$50 -> 1 | H18: ='6'!$G$61 -> 1 | I18: ='6'!$G$72 -> 1 | J18: ='6'!$G$83 -> 1 | K18: ='6'!$G$101 -> 0 | L18: ='6'!$G$112 -> 2 | M18: ='6'!$G$123 -> 0 | N18: ='6'!$G$134 -> 1 | O18: ='6'!$G$145 -> 3 | P18: ='6'!$G$156 -> 0 | Q18: ='6'!$G$167 -> 0 | R18: ='6'!$G$185 -> 0 | S18: ='6'!$G$196 -> 0 | T18: ='6'!$G$207 -> 0 | U18: ='6'!$G$218 -> 0 | V18: ='6'!$G$229 -> 0 | W18: ='6'!$G$240 -> 0 | X18: ='6'!$G$251 -> 0 | Y18: ='6'!$G$269 -> 0 | Z18: ='6'!$G$280 -> 0 | AA18: ='6'!$G$291 -> 0 | AB18: ='6'!$G$302 -> 0 | AC18: ='6'!$G$314 -> 1 | AD18: ='6'!$G$325 -> 2 | AE18: ='6'!$G$336 -> 0 | AF18: ='6'!$G$354 -> 1 | AG18: ='6'!$G$365 -> 2 | AH18: ='6'!$G$376 -> 0 | AI18: ='6'!$G$386 -> 0 | AJ18: ='6'!$G$397 -> 0 | AK18: ='6'!$G$408 -> 0 | AL18: ='6'!$G$419 -> 0 | AM18: =SUM(D18:AL18) -> 18 | AO18: =AM18*100 -> 1800
A19: 69001 | B19: นายธนพร สีหาด | C19: 8.00-17.00 | D19: ='7'!$F$17 -> 5 | E19: ='7'!$F$28 -> 5 | F19: ='7'!$F$39 -> 0 | G19: ='7'!$F$50 -> 0 | H19: ='7'!$F$61 -> 6 | I19: ='7'!$F$72 -> 6 | J19: ='7'!F83 -> 4 | K19: ='7'!F101 -> 6 | L19: ='7'!F112 -> 6 | M19: ='7'!F123 -> 4 | N19: ='7'!F134 -> 4 | O19: ='7'!F145 -> 0 | P19: ='7'!F156 -> 4 | Q19: ='7'!F167 -> 4 | R19: ='7'!F185 -> 5 | S19: ='7'!F196 -> 3 | T19: ='7'!F207 -> 4 | U19: ='7'!F218 -> 0 | V19: ='7'!F229 -> 0 | W19: ='7'!F240 -> 0 | X19: ='7'!F251 -> 0 | Y19: ='7'!F269 -> 0 | Z19: ='7'!F280 -> 0 | AA19: ='7'!F291 -> 0 | AB19: ='7'!F302 -> 2 | AC19: ='7'!F313 -> 7 | AD19: ='7'!F324 -> 6 | AE19: ='7'!F335 -> 5 | AF19: ='7'!F353 -> 5 | AG19: ='7'!F364 -> 5 | AH19: ='7'!F375 -> 0 | AI19: ='7'!$F$386 -> 0 | AJ19: ='7'!$F$397 -> 0 | AK19: ='7'!$F$408 -> 0 | AL19: ='7'!$F$419 -> 0 | AM19: =SUM(D19:AL19) -> 96 | AN19: =AM19*$AN$4 -> 7680 | AP19: =SUM(AN19:AO20) -> 9660 | AQ19: 0 | AR19: =SUM(AP19:AQ20) -> 9660
A20: ทะเบียน | B20: 53-0607 (7) | C20: หลัง 17.00 | D20: ='7'!$G$17 -> 0 | E20: ='7'!$G$28 -> 3 | F20: ='7'!$G$39 -> 0 | G20: ='7'!$G$50 -> 0 | H20: ='7'!$G$61 -> 1 | I20: ='7'!$G$72 -> 1 | J20: ='7'!$G$83 -> 0 | K20: ='7'!G101 -> 2 | L20: ='7'!G112 -> 3 | M20: ='7'!G124 -> 0 | N20: ='7'!G134 -> 2 | O20: ='7'!G146 -> 0 | P20: ='7'!G157 -> 0 | Q20: ='7'!G167 -> 0 | R20: ='7'!G185 -> 0 | S20: ='7'!G196 -> 2 | T20: ='7'!G207 -> 0 | U20: ='7'!G218 -> 0 | V20: ='7'!G229 -> 0 | W20: ='7'!G240 -> 0 | X20: ='7'!G251 -> 0 | Y20: ='7'!G269 -> 0 | Z20: ='7'!G280 -> 0 | AA20: ='7'!G291 -> 0 | AB20: ='7'!G302 -> 0 | AC20: ='7'!G313 -> 1 | AD20: ='7'!G324 -> 1 | AE20: ='7'!G335 -> 0 | AF20: ='7'!G353 -> 1 | AG20: ='7'!G364 -> 2 | AH20: ='7'!G375 -> 0 | AI20: ='7'!$G$386 -> 0 | AJ20: ='7'!$G$397 -> 0 | AK20: ='7'!$G$408 -> 0 | AL20: ='7'!$G$419 -> 0 | AM20: =SUM(D20:AL20) -> 19 | AN20: =40+40 -> 80 | AO20: =AM20*100 -> 1900
A21: 67007 | B21: นายพิทักษ์ โประณะ | C21: 8.00-17.00 | D21: ='8'!$F$17 -> 5 | E21: ='8'!$F$28 -> 6 | F21: ='8'!$F$39 -> 2 | G21: ='8'!$F$50 -> 3 | H21: ='8'!$F$61 -> 2 | I21: ='8'!$F$72 -> 5 | J21: ='8'!$F$83 -> 4 | K21: ='8'!$F$101 -> 6 | L21: ='8'!$F$112 -> 6 | M21: ='8'!$F$123 -> 4 | N21: ='8'!$F$134 -> 4 | O21: ='8'!$F$145 -> 4 | P21: ='8'!$F$156 -> 5 | Q21: ='8'!$F$167 -> 2 | R21: ='8'!$F$185 -> 6 | S21: ='8'!$F$196 -> 4 | T21: ='8'!$F$207 -> 4 | U21: ='8'!$F$218 -> 0 | V21: ='8'!$F$229 -> 0 | W21: ='8'!$F$240 -> 0 | X21: ='8'!$F$251 -> 0 | Y21: ='8'!$F$269 -> 0 | Z21: ='8'!$F$280 -> 0 | AA21: ='8'!$F$291 -> 0 | AB21: ='8'!$F$302 -> 2 | AC21: ='8'!$F$313 -> 5 | AD21: ='8'!$F$324 -> 5 | AE21: ='8'!$F$335 -> 4 | AF21: ='8'!$F$353 -> 6 | AG21: ='8'!$F$364 -> 0 | AH21: ='8'!$F$375 -> 0 | AI21: ='8'!$F$386 -> 0 | AJ21: ='8'!$F$397 -> 0 | AK21: ='8'!$F$408 -> 0 | AL21: ='8'!$F$419 -> 0 | AM21: =SUM(D21:AL21) -> 94 | AN21: =AM21*$AN$4 -> 7520 | AP21: =SUM(AN21:AO22) -> 9920 | AQ21: 900 | AR21: =SUM(AP21:AQ22) -> 10820
